Workbook

Sheet Ranking
A1: Squaring the Matrix: First Attempt
B2: Persentase Kerusakan Gedung | C2: Lokasi Gedung | D2: Usia Bangunan | E2: Jumlah Siswa | F2: Total Baris | G2: Eigen Vector
A3: Persentase Kerusakan Gedung | B3: {=MMULT(AHP!B2:E5,AHP!B2:E5)} -> 4 | C3: 6.9480418 | D3: 9.3145354 | E3: 29.150162 | F3: =SUM(B3:E3) -> 49.412739 | G3: =F3/$F$7 -> 0.45075914
A4: Lokasi Gedung | B4: 2.4345561 | C4: 4 | D4: 5.5307727 | E4: 18.400613 | F4: =SUM(B4:E4) -> 30.365942 | G4: =F4/$F$7 -> 0.27700804
A5: Usia Bangunan | B5: 1.9109424 | C5: 3.2801566 | D5: 4 | E5: 13.800119 | F5: =SUM(B5:E5) -> 22.991218 | G5: =F5/$F$7 -> 0.2097334
A6: Jumlah Siswa | B6: 0.55978366 | C6: 0.99587151 | D6: 1.2956047 | E6: 4 | F6: =SUM(B6:E6) -> 6.8512598 | G6: =F6/$F$7 -> 0.062499429
A7: Total | F7: =SUM(F3:F6) -> 109.62116 | G7: =SUM(G3:G6) -> 1
A9: Squaring the Matrix: Second Attempt
B10: Persentase Kerusakan Gedung | C10: Lokasi Gedung | D10: Usia Bangunan | E10: Jumlah Siswa | F10: Total Baris | G10: Eigen Vector
A11: Persentase Kerusakan Gedung | B11: {=MMULT(B3:E6,B3:E6)} -> 67.032722 | C11: 115.16728 | D11: 150.71141 | E11: 489.59121 | F11: =SUM(B11:E11) -> 822.50263 | G11: =F11/$F$15 -> 0.45363746
A12: Lokasi Gedung | B12: 40.3458 | C12: 69.381844 | D12: 90.762861 | E12: 294.49793 | F12: =SUM(B12:E12) -> 494.98843 | G12: =F12/$F$15 -> 0.27300253
A13: Usia Bangunan | B13: 30.998345 | C13: 53.261705 | D13: 69.820839 | E13: 226.46212 | F13: =SUM(B13:E13) -> 380.54301 | G13: =F13/$F$15 -> 0.20988208
A14: Jumlah Siswa | B14: 9.3786002 | C14: 16.106158 | D14: 21.086901 | E14: 68.521928 | F14: =SUM(B14:E14) -> 115.09359 | G14: =F14/$F$15 -> 0.063477929
A15: Total | F15: =SUM(F11:F14) -> 1813.1277 | G15: =SUM(G11:G14) -> 1
A17: First EV - Second EV
A18: Kategori | B18: Value | D18: Pertimbangan
A19: Persentase Kerusakan Gedung | B19: =G3-G11 -> -0.0028783224 | D19: Karena semua nilai First EV - Second EV seluruhnya sudah cukup kecil (mendekati 0), maka kita bisa gunakan EV terakhir sebagai bobot prioritas
A20: Lokasi Gedung | B20: =G4-G12 -> 0.0040055089
A21: Usia Bangunan | B21: =G5-G13 -> -0.00014868734
A22: Jumlah Siswa | B22: =G6-G14 -> -0.00097849912
A24: Kriteria | B24: Rank | C24: Priority
A25: Persentase Kerusakan Gedung | B25: =_xlfn.RANK.EQ(C25,$C$25:$C$28,0) -> 1 | C25: =G11 -> 0.45363746
A26: Lokasi Gedung | B26: =_xlfn.RANK.EQ(C26,$C$25:$C$28,0) -> 2 | C26: =G12 -> 0.27300253
A27: Usia Bangunan | B27: =_xlfn.RANK.EQ(C27,$C$25:$C$28,0) -> 3 | C27: =G13 -> 0.20988208
A28: Jumlah Siswa | B28: =_xlfn.RANK.EQ(C28,$C$25:$C$28,0) -> 4 | C28: =G14 -> 0.063477929

Sheet AHP
B1: Persentase Kerusakan Gedung | C1: Lokasi Gedung | D1: Usia Bangunan | E1: Jumlah Siswa
A2: Persentase Kerusakan Gedung | B2: 1 | C2: =GEOMEAN('Pairw Comp Matrix'!C4,'Pairw Comp Matrix'!C12,'Pairw Comp Matrix'!C20) -> 2 | D2: =GEOMEAN('Pairw Comp Matrix'!D4,'Pairw Comp Matrix'!D12,'Pairw Comp Matrix'!D20) -> 2.0800838 | E2: =GEOMEAN('Pairw Comp Matrix'!E4,'Pairw Comp Matrix'!E12,'Pairw Comp Matrix'!E20) -> 6.4633041
A3: Lokasi Gedung | B3: =1/C2 -> 0.5 | C3: 1 | D3: =GEOMEAN('Pairw Comp Matrix'!D5,'Pairw Comp Matrix'!D13,'Pairw Comp Matrix'!D21) -> 1.8392828 | E3: =GEOMEAN('Pairw Comp Matrix'!E5,'Pairw Comp Matrix'!E13,'Pairw Comp Matrix'!E21) -> 3.5568933
A4: Usia Bangunan | B4: =1/D2 -> 0.48074986 | C4: =1/D3 -> 0.54369019 | D4: 1 | E4: =GEOMEAN('Pairw Comp Matrix'!E6,'Pairw Comp Matrix'!E14,'Pairw Comp Matrix'!E22) -> 4.3795191
A5: Jumlah Siswa | B5: =1/E2 -> 0.15471963 | C5: =1/E3 -> 0.28114422 | D5: =1/E4 -> 0.22833557 | E5: 1
A6: Total | B6: =SUM(B2:B5) -> 2.1354695 | C6: =SUM(C2:C5) -> 3.8248344 | D6: =SUM(D2:D5) -> 5.1477022 | E6: =SUM(E2:E5) -> 15.399717
B9: Persentase Kerusakan Gedung | C9: Lokasi Gedung | D9: Usia Bangunan | E9: Jumlah Siswa | F9: Prioritas
A10: Persentase Kerusakan Gedung | B10: =B2/$B$6 -> 0.4682811 | C10: =C2/$C$6 -> 0.52289845 | D10: =D2/$D$6 -> 0.40408006 | E10: =E2/$E$6 -> 0.4197028 | F10: =AVERAGE(B10:E10) -> 0.4537406
A11: Lokasi Gedung | B11: =B3/$B$6 -> 0.23414055 | C11: =C3/$C$6 -> 0.26144923 | D11: =D3/$D$6 -> 0.35730171 | E11: =E3/$E$6 -> 0.23097135 | F11: =AVERAGE(B11:E11) -> 0.27096571
A12: Usia Bangunan | B12: =B4/$B$6 -> 0.22512607 | C12: =C4/$C$6 -> 0.14214738 | D12: =D4/$D$6 -> 0.19426143 | E12: =E4/$E$6 -> 0.28438959 | F12: =AVERAGE(B12:E12) -> 0.21148112
A13: Jumlah Siswa | B13: =B5/$B$6 -> 0.072452278 | C13: =C5/$C$6 -> 0.073504939 | D13: =D5/$D$6 -> 0.044356795 | E13: =E5/$E$6 -> 0.06493626 | F13: =AVERAGE(B13:E13) -> 0.063812568
A14: Total | B14: =SUM(B10:B13) -> 1 | C14: =SUM(C10:C13) -> 1 | D14: =SUM(D10:D13) -> 1 | E14: =SUM(E10:E13) -> 1 | F14: =SUM(F10:F13) -> 1
A17: Parameter | B17: Value | C17: Conclusion
A18: Max Eigen Value | B18: =MMULT(B6:E6,F10:F13) -> 4.0766855 | C18: =IF(B22<=0.1,"Konsistensi Baik/Acceptable","Konsistensi Buruk") -> Konsistensi Baik/Acceptable
A19: Jumlah Kategori yang Ada | B19: 4
A20: CI | B20: =(B18-B19)/(B19-1) -> 0.025561819
A21: RI | B21: =INDEX(B26:K26, MATCH(B19, B25:K25, 0)) -> 0.9
A22: CR = CI/RI | B22: =B20/B21 -> 0.028402021
A24: Tabel Random Consistency Ratio (RI)
A25: Jumlah Kategori | B25: 1 | C25: 2 | D25: 3 | E25: 4 | F25: 5 | G25: 6 | H25: 7 | I25: 8 | J25: 9 | K25: 10
A26: RI | B26: 0 | C26: 0 | D26: 0.58 | E26: 0.9 | F26: 1.12 | G26: 1.24 | H26: 1.32 | I26: 1.41 | J26: 1.45 | K26: 1.49

Sheet Pairw Comp Matrix
A1: PENGAWAS SEKOLAH DASAR KAPUAS BARAT (JHON)
B3: PERSENTASE KERUSAKAN GEDUNG | C3: LOKASI GEDUNG | D3: USIA BANGUNAN | E3: JUMLAH SISWA
A4: PERSENTASE KERUSAKAN GEDUNG | B4: 1 | C4: 4 | D4: 6 | E4: 6
A5: LOKASI GEDUNG | B5: =1/C4 -> 0.25 | C5: 1 | D5: 8 | E5: 9
A6: USIA BANGUNAN | B6: =1/D4 -> 0.16666667 | C6: =1/D5 -> 0.125 | D6: 1 | E6: 7
A7: JUMLAH SISWA | B7: =1/E4 -> 0.16666667 | C7: =1/E5 -> 0.11111111 | D7: =1/E6 -> 0.14285714 | E7: 1
A9: KEPALA BIDANG PENGAWASAN SEKOLAH DASAR DISDIK KAPUAS (JEFRI)
B11: PERSENTASE KERUSAKAN GEDUNG | C11: LOKASI GEDUNG | D11: USIA BANGUNAN | E11: JUMLAH SISWA
A12: PERSENTASE KERUSAKAN GEDUNG | B12: 1 | C12: =1/4 -> 0.25 | D12: =1/4 -> 0.25 | E12: 9
A13: LOKASI GEDUNG | B13: =1/C12 -> 4 | C13: 1 | D13: =1/9 -> 0.11111111 | E13: 1
A14: USIA BANGUNAN | B14: =1/D12 -> 4 | C14: =1/D13 -> 9 | D14: 1 | E14: 3
A15: JUMLAH SISWA | B15: =1/E12 -> 0.11111111 | C15: =1/E13 -> 1 | D15: =1/E14 -> 0.33333333 | E15: 1
A17: KOMISI IV DPRD KAB. KAPUAS
B19: PERSENTASE KERUSAKAN GEDUNG | C19: LOKASI GEDUNG | D19: USIA BANGUNAN | E19: JUMLAH SISWA
A20: PERSENTASE KERUSAKAN GEDUNG | B20: 1 | C20: 8 | D20: 6 | E20: 5
A21: LOKASI GEDUNG | B21: =1/C20 -> 0.125 | C21: 1 | D21: 7 | E21: 5
A22: USIA BANGUNAN | B22: =1/D20 -> 0.16666667 | C22: =1/D21 -> 0.14285714 | D22: 1 | E22: 4
A23: JUMLAH SISWA | B23: =1/E20 -> 0.2 | C23: =1/E21 -> 0.2 | D23: =1/E22 -> 0.25 | E23: 1

Sheet PERBANDINGAN KRITERIA
B1: PERBANDINGAN KRITERIA | V1: PERBANDINGAN KRITERIA | AP1: PERBANDINGAN KRITERIA
B2: PENGAWAS SEKOLAH DASAR KAPUAS BARAT (JHON) | V2: KEPALA BIDANG PENGAWASAN SEKOLAH DASAR DISDIK KAPUAS (JEFRI) | AP2: KOMISI IV DPRD KAB. KAPUAS | BJ2: PANDUAN PENGISIAN | BN2: CONDONG KE A | BV2: NETRAL | BW2: CONDONG KE B
B3: KRITERIA UTAMA | C3: KRITERIA NILAI | T3: KRITERIA PEMBANDING | V3: KRITERIA UTAMA | W3: KRITERIA NILAI | AN3: KRITERIA PEMBANDING | AP3: KRITERIA UTAMA | AQ3: KRITERIA NILAI | BH3: KRITERIA PEMBANDING | BJ3: TINGKAT KEPENTINGAN | BK3: DEFINISI | BM3: PILIHAN A | BN3: 9 | BO3: 8 | BP3: 7 | BQ3: 6 | BR3: 5 | BS3: 4 | BT3: 3 | BU3: 2 | BV3: 1 | BW3: 2 | BX3: 3 | BY3: 4 | BZ3: 5 | CA3: 6 | CB3: 7 | CC3: 8 | CD3: 9 | CE3: PILIHAN B
C4: 9 | D4: 8 | E4: 7 | F4: 6 | G4: 5 | H4: 4 | I4: 3 | J4: 2 | K4: 1 | L4: 2 | M4: 3 | N4: 4 | O4: 5 | P4: 6 | Q4: 7 | R4: 8 | S4: 9 | W4: 9 | X4: 8 | Y4: 7 | Z4: 6 | AA4: 5 | AB4: 4 | AC4: 3 | AD4: 2 | AE4: 1 | AF4: 2 | AG4: 3 | AH4: 4 | AI4: 5 | AJ4: 6 | AK4: 7 | AL4: 8 | AM4: 9 | AQ4: 9 | AR4: 8 | AS4: 7 | AT4: 6 | AU4: 5 | AV4: 4 | AW4: 3 | AX4: 2 | AY4: 1 | AZ4: 2 | BA4: 3 | BB4: 4 | BC4: 5 | BD4: 6 | BE4: 7 | BF4: 8 | BG4: 9 | BJ4: 1 | BK4: KEDUA ELEMEN SAMA PENTING
B5: PERSENTASE KERUSAKAN GEDUNG | C5: 9 | D5: 8 | E5: 7 | F5: 6 | G5: 5 | H5: 4 | I5: 3 | J5: 2 | K5: 1 | L5: 2 | M5: 3 | N5: 4 | O5: 5 | P5: 6 | Q5: 7 | R5: 8 | S5: 9 | T5: LOKASI GFEDUNG | V5: PERSENTASE KERUSAKAN GEDUNG | W5: 9 | X5: 8 | Y5: 7 | Z5: 6 | AA5: 5 | AB5: 4 | AC5: 3 | AD5: 2 | AE5: 1 | AF5: 2 | AG5: 3 | AH5: 4 | AI5: 5 | AJ5: 6 | AK5: 7 | AL5: 8 | AM5: 9 | AN5: LOKASI GFEDUNG | AP5: PERSENTASE KERUSAKAN GEDUNG | AQ5: 9 | AR5: 8 | AS5: 7 | AT5: 6 | AU5: 5 | AV5: 4 | AW5: 3 | AX5: 2 | AY5: 1 | AZ5: 2 | BA5: 3 | BB5: 4 | BC5: 5 | BD5: 6 | BE5: 7 | BF5: 8 | BG5: 9 | BH5: LOKASI GFEDUNG | BJ5: 3 | BK5: ELEMEN YANG SATU SEDIKIT LEBIH PENTING DARI YANG LAIN
B6: PERSENTASE KERUSAKAN GEDUNG | C6: 9 | D6: 8 | E6: 7 | F6: 6 | G6: 5 | H6: 4 | I6: 3 | J6: 2 | K6: 1 | L6: 2 | M6: 3 | N6: 4 | O6: 5 | P6: 6 | Q6: 7 | R6: 8 | S6: 9 | T6: USIA BANGUNAN | V6: PERSENTASE KERUSAKAN GEDUNG | W6: 9 | X6: 8 | Y6: 7 | Z6: 6 | AA6: 5 | AB6: 4 | AC6: 3 | AD6: 2 | AE6: 1 | AF6: 2 | AG6: 3 | AH6: 4 | AI6: 5 | AJ6: 6 | AK6: 7 | AL6: 8 | AM6: 9 | AN6: USIA BANGUNAN | AP6: PERSENTASE KERUSAKAN GEDUNG | AQ6: 9 | AR6: 8 | AS6: 7 | AT6: 6 | AU6: 5 | AV6: 4 | AW6: 3 | AX6: 2 | AY6: 1 | AZ6: 2 | BA6: 3 | BB6: 4 | BC6: 5 | BD6: 6 | BE6: 7 | BF6: 8 | BG6: 9 | BH6: USIA BANGUNAN | BJ6: 5 | BK6: ELEMEN YANG SATU LEBIH PENTING DARI YANG LAIN
B7: PERSENTASE KERUSAKAN GEDUNG | C7: 9 | D7: 8 | E7: 7 | F7: 6 | G7: 5 | H7: 4 | I7: 3 | J7: 2 | K7: 1 | L7: 2 | M7: 3 | N7: 4 | O7: 5 | P7: 6 | Q7: 7 | R7: 8 | S7: 9 | T7: JUMLAH SISWA | V7: PERSENTASE KERUSAKAN GEDUNG | W7: 9 | X7: 8 | Y7: 7 | Z7: 6 | AA7: 5 | AB7: 4 | AC7: 3 | AD7: 2 | AE7: 1 | AF7: 2 | AG7: 3 | AH7: 4 | AI7: 5 | AJ7: 6 | AK7: 7 | AL7: 8 | AM7: 9 | AN7: JUMLAH SISWA | AP7: PERSENTASE KERUSAKAN GEDUNG | AQ7: 9 | AR7: 8 | AS7: 7 | AT7: 6 | AU7: 5 | AV7: 4 | AW7: 3 | AX7: 2 | AY7: 1 | AZ7: 2 | BA7: 3 | BB7: 4 | BC7: 5 | BD7: 6 | BE7: 7 | BF7: 8 | BG7: 9 | BH7: JUMLAH SISWA | BJ7: 7 | BK7: ELEMEN YANG SATU SANGAT PENTING DARI YANG LAIN
B8: LOKASI GEDUNG | C8: 9 | D8: 8 | E8: 7 | F8: 6 | G8: 5 | H8: 4 | I8: 3 | J8: 2 | K8: 1 | L8: 2 | M8: 3 | N8: 4 | O8: 5 | P8: 6 | Q8: 7 | R8: 8 | S8: 9 | T8: USIA BANGUNAN | V8: LOKASI GEDUNG | W8: 9 | X8: 8 | Y8: 7 | Z8: 6 | AA8: 5 | AB8: 4 | AC8: 3 | AD8: 2 | AE8: 1 | AF8: 2 | AG8: 3 | AH8: 4 | AI8: 5 | AJ8: 6 | AK8: 7 | AL8: 8 | AM8: 9 | AN8: USIA BANGUNAN | AP8: LOKASI GEDUNG | AQ8: 9 | AR8: 8 | AS8: 7 | AT8: 6 | AU8: 5 | AV8: 4 | AW8: 3 | AX8: 2 | AY8: 1 | AZ8: 2 | BA8: 3 | BB8: 4 | BC8: 5 | BD8: 6 | BE8: 7 | BF8: 8 | BG8: 9 | BH8: USIA BANGUNAN | BJ8: 9 | BK8: ELEMEN YANG SATU MUTLAK LEBIH PENTING DARI YANG LAIN
B9: LOKASI GEDUNG | C9: 9 | D9: 8 | E9: 7 | F9: 6 | G9: 5 | H9: 4 | I9: 3 | J9: 2 | K9: 1 | L9: 2 | M9: 3 | N9: 4 | O9: 5 | P9: 6 | Q9: 7 | R9: 8 | S9: 9 | T9: JUMLAH SISWA | V9: LOKASI GEDUNG | W9: 9 | X9: 8 | Y9: 7 | Z9: 6 | AA9: 5 | AB9: 4 | AC9: 3 | AD9: 2 | AE9: 1 | AF9: 2 | AG9: 3 | AH9: 4 | AI9: 5 | AJ9: 6 | AK9: 7 | AL9: 8 | AM9: 9 | AN9: JUMLAH SISWA | AP9: LOKASI GEDUNG | AQ9: 9 | AR9: 8 | AS9: 7 | AT9: 6 | AU9: 5 | AV9: 4 | AW9: 3 | AX9: 2 | AY9: 1 | AZ9: 2 | BA9: 3 | BB9: 4 | BC9: 5 | BD9: 6 | BE9: 7 | BF9: 8 | BG9: 9 | BH9: JUMLAH SISWA | BJ9: 2,4,6,8 | BK9: NILAI KOMPROMI (NILAI TENGAH ANTARA DUA PERBANDINGAN)
B10: USIA BANGUNAN | C10: 9 | D10: 8 | E10: 7 | F10: 6 | G10: 5 | H10: 4 | I10: 3 | J10: 2 | K10: 1 | L10: 2 | M10: 3 | N10: 4 | O10: 5 | P10: 6 | Q10: 7 | R10: 8 | S10: 9 | T10: JUMLAH SISWA | V10: USIA BANGUNAN | W10: 9 | X10: 8 | Y10: 7 | Z10: 6 | AA10: 5 | AB10: 4 | AC10: 3 | AD10: 2 | AE10: 1 | AF10: 2 | AG10: 3 | AH10: 4 | AI10: 5 | AJ10: 6 | AK10: 7 | AL10: 8 | AM10: 9 | AN10: JUMLAH SISWA | AP10: USIA BANGUNAN | AQ10: 9 | AR10: 8 | AS10: 7 | AT10: 6 | AU10: 5 | AV10: 4 | AW10: 3 | AX10: 2 | AY10: 1 | AZ10: 2 | BA10: 3 | BB10: 4 | BC10: 5 | BD10: 6 | BE10: 7 | BF10: 8 | BG10: 9 | BH10: JUMLAH SISWA

Sheet PERSENTASE KERUSAKAN GEDUNG
B1: PERSENTASE KERUSAKAN GEDUNG | V1: PERSENTASE KERUSAKAN GEDUNG | AP1: PERSENTASE KERUSAKAN GEDUNG
B2: PENGAWAS SEKOLAH DASAR KAPUAS BARAT (JHON) | V2: KEPALA BIDANG PENGAWASAN SEKOLAH DASAR DISDIK KAPUAS (JEFRI) | AP2: KOMISI IV DPRD KAB. KAPUAS
B3: SEKOLAH UTAMA | C3: KRITERIA NILAI | T3: SEKOLAH PEMBANDING | V3: SEKOLAH UTAMA | W3: KRITERIA NILAI | AN3: SEKOLAH PEMBANDING | AP3: SEKOLAH UTAMA | AQ3: KRITERIA NILAI | BH3: SEKOLAH PEMBANDING
C4: 9 | D4: 8 | E4: 7 | F4: 6 | G4: 5 | H4: 4 | I4: 3 | J4: 2 | K4: 1 | L4: 2 | M4: 3 | N4: 4 | O4: 5 | P4: 6 | Q4: 7 | R4: 8 | S4: 9 | W4: 9 | X4: 8 | Y4: 7 | Z4: 6 | AA4: 5 | AB4: 4 | AC4: 3 | AD4: 2 | AE4: 1 | AF4: 2 | AG4: 3 | AH4: 4 | AI4: 5 | AJ4: 6 | AK4: 7 | AL4: 8 | AM4: 9 | AQ4: 9 | AR4: 8 | AS4: 7 | AT4: 6 | AU4: 5 | AV4: 4 | AW4: 3 | AX4: 2 | AY4: 1 | AZ4: 2 | BA4: 3 | BB4: 4 | BC4: 5 | BD4: 6 | BE4: 7 | BF4: 8 | BG4: 9
B5: SDN-2 ANJIR KALAMPAN | C5: 9 | D5: 8 | E5: 7 | F5: 6 | G5: 5 | H5: 4 | I5: 3 | J5: 2 | K5: 1 | L5: 2 | M5: 3 | N5: 4 | O5: 5 | P5: 6 | Q5: 7 | R5: 8 | S5: 9 | T5: SDN-3 ANJIR KALAMPAN | V5: SDN-2 ANJIR KALAMPAN | W5: 9 | X5: 8 | Y5: 7 | Z5: 6 | AA5: 5 | AB5: 4 | AC5: 3 | AD5: 2 | AE5: 1 | AF5: 2 | AG5: 3 | AH5: 4 | AI5: 5 | AJ5: 6 | AK5: 7 | AL5: 8 | AM5: 9 | AN5: SDN-3 ANJIR KALAMPAN | AP5: SDN-2 ANJIR KALAMPAN | AQ5: 9 | AR5: 8 | AS5: 7 | AT5: 6 | AU5: 5 | AV5: 4 | AW5: 3 | AX5: 2 | AY5: 1 | AZ5: 2 | BA5: 3 | BB5: 4 | BC5: 5 | BD5: 6 | BE5: 7 | BF5: 8 | BG5: 9 | BH5: SDN-3 ANJIR KALAMPAN
B6: SDN-2 ANJIR KALAMPAN | C6: 9 | D6: 8 | E6: 7 | F6: 6 | G6: 5 | H6: 4 | I6: 3 | J6: 2 | K6: 1 | L6: 2 | M6: 3 | N6: 4 | O6: 5 | P6: 6 | Q6: 7 | R6: 8 | S6: 9 | T6: SDN-1 SAKA MANGKAHAI | V6: SDN-2 ANJIR KALAMPAN | W6: 9 | X6: 8 | Y6: 7 | Z6: 6 | AA6: 5 | AB6: 4 | AC6: 3 | AD6: 2 | AE6: 1 | AF6: 2 | AG6: 3 | AH6: 4 | AI6: 5 | AJ6: 6 | AK6: 7 | AL6: 8 | AM6: 9 | AN6: SDN-1 SAKA MANGKAHAI | AP6: SDN-2 ANJIR KALAMPAN | AQ6: 9 | AR6: 8 | AS6: 7 | AT6: 6 | AU6: 5 | AV6: 4 | AW6: 3 | AX6: 2 | AY6: 1 | AZ6: 2 | BA6: 3 | BB6: 4 | BC6: 5 | BD6: 6 | BE6: 7 | BF6: 8 | BG6: 9 | BH6: SDN-1 SAKA MANGKAHAI | BJ6: PANDUAN PENGISIAN | BN6: CONDONG KE A | BV6: NETRAL | BW6: CONDONG KE B
B7: SDN-2 ANJIR KALAMPAN | C7: 9 | D7: 8 | E7: 7 | F7: 6 | G7: 5 | H7: 4 | I7: 3 | J7: 2 | K7: 1 | L7: 2 | M7: 3 | N7: 4 | O7: 5 | P7: 6 | Q7: 7 | R7: 8 | S7: 9 | T7: SDN-2 SAKA MANGKAHAI | V7: SDN-2 ANJIR KALAMPAN | W7: 9 | X7: 8 | Y7: 7 | Z7: 6 | AA7: 5 | AB7: 4 | AC7: 3 | AD7: 2 | AE7: 1 | AF7: 2 | AG7: 3 | AH7: 4 | AI7: 5 | AJ7: 6 | AK7: 7 | AL7: 8 | AM7: 9 | AN7: SDN-2 SAKA MANGKAHAI | AP7: SDN-2 ANJIR KALAMPAN | AQ7: 9 | AR7: 8 | AS7: 7 | AT7: 6 | AU7: 5 | AV7: 4 | AW7: 3 | AX7: 2 | AY7: 1 | AZ7: 2 | BA7: 3 | BB7: 4 | BC7: 5 | BD7: 6 | BE7: 7 | BF7: 8 | BG7: 9 | BH7: SDN-2 SAKA MANGKAHAI | BJ7: TINGKAT KEPENTINGAN | BK7: DEFINISI | BM7: PILIHAN A | BN7: 9 | BO7: 8 | BP7: 7 | BQ7: 6 | BR7: 5 | BS7: 4 | BT7: 3 | BU7: 2 | BV7: 1 | BW7: 2 | BX7: 3 | BY7: 4 | BZ7: 5 | CA7: 6 | CB7: 7 | CC7: 8 | CD7: 9 | CE7: PILIHAN B
B8: SDN-2 ANJIR KALAMPAN | C8: 9 | D8: 8 | E8: 7 | F8: 6 | G8: 5 | H8: 4 | I8: 3 | J8: 2 | K8: 1 | L8: 2 | M8: 3 | N8: 4 | O8: 5 | P8: 6 | Q8: 7 | R8: 8 | S8: 9 | T8: SDN-2 MANDOMAI | V8: SDN-2 ANJIR KALAMPAN | W8: 9 | X8: 8 | Y8: 7 | Z8: 6 | AA8: 5 | AB8: 4 | AC8: 3 | AD8: 2 | AE8: 1 | AF8: 2 | AG8: 3 | AH8: 4 | AI8: 5 | AJ8: 6 | AK8: 7 | AL8: 8 | AM8: 9 | AN8: SDN-2 MANDOMAI | AP8: SDN-2 ANJIR KALAMPAN | AQ8: 9 | AR8: 8 | AS8: 7 | AT8: 6 | AU8: 5 | AV8: 4 | AW8: 3 | AX8: 2 | AY8: 1 | AZ8: 2 | BA8: 3 | BB8: 4 | BC8: 5 | BD8: 6 | BE8: 7 | BF8: 8 | BG8: 9 | BH8: SDN-2 MANDOMAI | BJ8: 1 | BK8: KEDUA ELEMEN SAMA PENTING
B9: SDN-2 ANJIR KALAMPAN | C9: 9 | D9: 8 | E9: 7 | F9: 6 | G9: 5 | H9: 4 | I9: 3 | J9: 2 | K9: 1 | L9: 2 | M9: 3 | N9: 4 | O9: 5 | P9: 6 | Q9: 7 | R9: 8 | S9: 9 | T9: SDN-3 MANDOMAI | V9: SDN-2 ANJIR KALAMPAN | W9: 9 | X9: 8 | Y9: 7 | Z9: 6 | AA9: 5 | AB9: 4 | AC9: 3 | AD9: 2 | AE9: 1 | AF9: 2 | AG9: 3 | AH9: 4 | AI9: 5 | AJ9: 6 | AK9: 7 | AL9: 8 | AM9: 9 | AN9: SDN-3 MANDOMAI | AP9: SDN-2 ANJIR KALAMPAN | AQ9: 9 | AR9: 8 | AS9: 7 | AT9: 6 | AU9: 5 | AV9: 4 | AW9: 3 | AX9: 2 | AY9: 1 | AZ9: 2 | BA9: 3 | BB9: 4 | BC9: 5 | BD9: 6 | BE9: 7 | BF9: 8 | BG9: 9 | BH9: SDN-3 MANDOMAI | BJ9: 3 | BK9: ELEMEN YANG SATU SEDIKIT LEBIH PENTING DARI YANG LAIN
B10: SDN-2 ANJIR KALAMPAN | C10: 9 | D10: 8 | E10: 7 | F10: 6 | G10: 5 | H10: 4 | I10: 3 | J10: 2 | K10: 1 | L10: 2 | M10: 3 | N10: 4 | O10: 5 | P10: 6 | Q10: 7 | R10: 8 | S10: 9 | T10: SDN-4 MANDOMAI | V10: SDN-2 ANJIR KALAMPAN | W10: 9 | X10: 8 | Y10: 7 | Z10: 6 | AA10: 5 | AB10: 4 | AC10: 3 | AD10: 2 | AE10: 1 | AF10: 2 | AG10: 3 | AH10: 4 | AI10: 5 | AJ10: 6 | AK10: 7 | AL10: 8 | AM10: 9 | AN10: SDN-4 MANDOMAI | AP10: SDN-2 ANJIR KALAMPAN | AQ10: 9 | AR10: 8 | AS10: 7 | AT10: 6 | AU10: 5 | AV10: 4 | AW10: 3 | AX10: 2 | AY10: 1 | AZ10: 2 | BA10: 3 | BB10: 4 | BC10: 5 | BD10: 6 | BE10: 7 | BF10: 8 | BG10: 9 | BH10: SDN-4 MANDOMAI | BJ10: 5 | BK10: ELEMEN YANG SATU LEBIH PENTING DARI YANG LAIN
B11: SDN-2 ANJIR KALAMPAN | C11: 9 | D11: 8 | E11: 7 | F11: 6 | G11: 5 | H11: 4 | I11: 3 | J11: 2 | K11: 1 | L11: 2 | M11: 3 | N11: 4 | O11: 5 | P11: 6 | Q11: 7 | R11: 8 | S11: 9 | T11: SDN-1 PANTAI | V11: SDN-2 ANJIR KALAMPAN | W11: 9 | X11: 8 | Y11: 7 | Z11: 6 | AA11: 5 | AB11: 4 | AC11: 3 | AD11: 2 | AE11: 1 | AF11: 2 | AG11: 3 | AH11: 4 | AI11: 5 | AJ11: 6 | AK11: 7 | AL11: 8 | AM11: 9 | AN11: SDN-1 PANTAI | AP11: SDN-2 ANJIR KALAMPAN | AQ11: 9 | AR11: 8 | AS11: 7 | AT11: 6 | AU11: 5 | AV11: 4 | AW11: 3 | AX11: 2 | AY11: 1 | AZ11: 2 | BA11: 3 | BB11: 4 | BC11: 5 | BD11: 6 | BE11: 7 | BF11: 8 | BG11: 9 | BH11: SDN-1 PANTAI | BJ11: 7 | BK11: ELEMEN YANG SATU SANGAT PENTING DARI YANG LAIN
B12: SDN-2 ANJIR KALAMPAN | C12: 9 | D12: 8 | E12: 7 | F12: 6 | G12: 5 | H12: 4 | I12: 3 | J12: 2 | K12: 1 | L12: 2 | M12: 3 | N12: 4 | O12: 5 | P12: 6 | Q12: 7 | R12: 8 | S12: 9 | T12: SDN-2 PANTAI | V12: SDN-2 ANJIR KALAMPAN | W12: 9 | X12: 8 | Y12: 7 | Z12: 6 | AA12: 5 | AB12: 4 | AC12: 3 | AD12: 2 | AE12: 1 | AF12: 2 | AG12: 3 | AH12: 4 | AI12: 5 | AJ12: 6 | AK12: 7 | AL12: 8 | AM12: 9 | AN12: SDN-2 PANTAI | AP12: SDN-2 ANJIR KALAMPAN | AQ12: 9 | AR12: 8 | AS12: 7 | AT12: 6 | AU12: 5 | AV12: 4 | AW12: 3 | AX12: 2 | AY12: 1 | AZ12: 2 | BA12: 3 | BB12: 4 | BC12: 5 | BD12: 6 | BE12: 7 | BF12: 8 | BG12: 9 | BH12: SDN-2 PANTAI | BJ12: 9 | BK12: ELEMEN YANG SATU MUTLAK LEBIH PENTING DARI YANG LAIN
B13: SDN-2 ANJIR KALAMPAN | C13: 9 | D13: 8 | E13: 7 | F13: 6 | G13: 5 | H13: 4 | I13: 3 | J13: 2 | K13: 1 | L13: 2 | M13: 3 | N13: 4 | O13: 5 | P13: 6 | Q13: 7 | R13: 8 | S13: 9 | T13: SDN-1 BASUTA RAYA | V13: SDN-2 ANJIR KALAMPAN | W13: 9 | X13: 8 | Y13: 7 | Z13: 6 | AA13: 5 | AB13: 4 | AC13: 3 | AD13: 2 | AE13: 1 | AF13: 2 | AG13: 3 | AH13: 4 | AI13: 5 | AJ13: 6 | AK13: 7 | AL13: 8 | AM13: 9 | AN13: SDN-1 BASUTA RAYA | AP13: SDN-2 ANJIR KALAMPAN | AQ13: 9 | AR13: 8 | AS13: 7 | AT13: 6 | AU13: 5 | AV13: 4 | AW13: 3 | AX13: 2 | AY13: 1 | AZ13: 2 | BA13: 3 | BB13: 4 | BC13: 5 | BD13: 6 | BE13: 7 | BF13: 8 | BG13: 9 | BH13: SDN-1 BASUTA RAYA | BJ13: 2,4,6,8 | BK13: NILAI KOMPROMI (NILAI TENGAH ANTARA DUA PERBANDINGAN)
B14: SDN-2 ANJIR KALAMPAN | C14: 9 | D14: 8 | E14: 7 | F14: 6 | G14: 5 | H14: 4 | I14: 3 | J14: 2 | K14: 1 | L14: 2 | M14: 3 | N14: 4 | O14: 5 | P14: 6 | Q14: 7 | R14: 8 | S14: 9 | T14: SDN-1 SEI PITUNG | V14: SDN-2 ANJIR KALAMPAN | W14: 9 | X14: 8 | Y14: 7 | Z14: 6 | AA14: 5 | AB14: 4 | AC14: 3 | AD14: 2 | AE14: 1 | AF14: 2 | AG14: 3 | AH14: 4 | AI14: 5 | AJ14: 6 | AK14: 7 | AL14: 8 | AM14: 9 | AN14: SDN-1 SEI PITUNG | AP14: SDN-2 ANJIR KALAMPAN | AQ14: 9 | AR14: 8 | AS14: 7 | AT14: 6 | AU14: 5 | AV14: 4 | AW14: 3 | AX14: 2 | AY14: 1 | AZ14: 2 | BA14: 3 | BB14: 4 | BC14: 5 | BD14: 6 | BE14: 7 | BF14: 8 | BG14: 9 | BH14: SDN-1 SEI PITUNG
B15: SDN-2 ANJIR KALAMPAN | C15: 9 | D15: 8 | E15: 7 | F15: 6 | G15: 5 | H15: 4 | I15: 3 | J15: 2 | K15: 1 | L15: 2 | M15: 3 | N15: 4 | O15: 5 | P15: 6 | Q15: 7 | R15: 8 | S15: 9 | T15: SDN-1 PENDA KATAPI | V15: SDN-2 ANJIR KALAMPAN | W15: 9 | X15: 8 | Y15: 7 | Z15: 6 | AA15: 5 | AB15: 4 | AC15: 3 | AD15: 2 | AE15: 1 | AF15: 2 | AG15: 3 | AH15: 4 | AI15: 5 | AJ15: 6 | AK15: 7 | AL15: 8 | AM15: 9 | AN15: SDN-1 PENDA KATAPI | AP15: SDN-2 ANJIR KALAMPAN | AQ15: 9 | AR15: 8 | AS15: 7 | AT15: 6 | AU15: 5 | AV15: 4 | AW15: 3 | AX15: 2 | AY15: 1 | AZ15: 2 | BA15: 3 | BB15: 4 | BC15: 5 | BD15: 6 | BE15: 7 | BF15: 8 | BG15: 9 | BH15: SDN-1 PENDA KATAPI
B16: SDN-2 ANJIR KALAMPAN | C16: 9 | D16: 8 | E16: 7 | F16: 6 | G16: 5 | H16: 4 | I16: 3 | J16: 2 | K16: 1 | L16: 2 | M16: 3 | N16: 4 | O16: 5 | P16: 6 | Q16: 7 | R16: 8 | S16: 9 | T16: SDN-1 SEI KAYU | V16: SDN-2 ANJIR KALAMPAN | W16: 9 | X16: 8 | Y16: 7 | Z16: 6 | AA16: 5 | AB16: 4 | AC16: 3 | AD16: 2 | AE16: 1 | AF16: 2 | AG16: 3 | AH16: 4 | AI16: 5 | AJ16: 6 | AK16: 7 | AL16: 8 | AM16: 9 | AN16: SDN-1 SEI KAYU | AP16: SDN-2 ANJIR KALAMPAN | AQ16: 9 | AR16: 8 | AS16: 7 | AT16: 6 | AU16: 5 | AV16: 4 | AW16: 3 | AX16: 2 | AY16: 1 | AZ16: 2 | BA16: 3 | BB16: 4 | BC16: 5 | BD16: 6 | BE16: 7 | BF16: 8 | BG16: 9 | BH16: SDN-1 SEI KAYU
B17: SDN-2 ANJIR KALAMPAN | C17: 9 | D17: 8 | E17: 7 | F17: 6 | G17: 5 | H17: 4 | I17: 3 | J17: 2 | K17: 1 | L17: 2 | M17: 3 | N17: 4 | O17: 5 | P17: 6 | Q17: 7 | R17: 8 | S17: 9 | T17: SDN-2 SEI KAYU | V17: SDN-2 ANJIR KALAMPAN | W17: 9 | X17: 8 | Y17: 7 | Z17: 6 | AA17: 5 | AB17: 4 | AC17: 3 | AD17: 2 | AE17: 1 | AF17: 2 | AG17: 3 | AH17: 4 | AI17: 5 | AJ17: 6 | AK17: 7 | AL17: 8 | AM17: 9 | AN17: SDN-2 SEI KAYU | AP17: SDN-2 ANJIR KALAMPAN | AQ17: 9 | AR17: 8 | AS17: 7 | AT17: 6 | AU17: 5 | AV17: 4 | AW17: 3 | AX17: 2 | AY17: 1 | AZ17: 2 | BA17: 3 | BB17: 4 | BC17: 5 | BD17: 6 | BE17: 7 | BF17: 8 | BG17: 9 | BH17: SDN-2 SEI KAYU
B18: SDN-2 ANJIR KALAMPAN | C18: 9 | D18: 8 | E18: 7 | F18: 6 | G18: 5 | H18: 4 | I18: 3 | J18: 2 | K18: 1 | L18: 2 | M18: 3 | N18: 4 | O18: 5 | P18: 6 | Q18: 7 | R18: 8 | S18: 9 | T18: SDN-1 SEI DUSUN | V18: SDN-2 ANJIR KALAMPAN | W18: 9 | X18: 8 | Y18: 7 | Z18: 6 | AA18: 5 | AB18: 4 | AC18: 3 | AD18: 2 | AE18: 1 | AF18: 2 | AG18: 3 | AH18: 4 | AI18: 5 | AJ18: 6 | AK18: 7 | AL18: 8 | AM18: 9 | AN18: SDN-1 SEI DUSUN | AP18: SDN-2 ANJIR KALAMPAN | AQ18: 9 | AR18: 8 | AS18: 7 | AT18: 6 | AU18: 5 | AV18: 4 | AW18: 3 | AX18: 2 | AY18: 1 | AZ18: 2 | BA18: 3 | BB18: 4 | BC18: 5 | BD18: 6 | BE18: 7 | BF18: 8 | BG18: 9 | BH18: SDN-1 SEI DUSUN
B19: SDN-3 ANJIR KALAMPAN | C19: 9 | D19: 8 | E19: 7 | F19: 6 | G19: 5 | H19: 4 | I19: 3 | J19: 2 | K19: 1 | L19: 2 | M19: 3 | N19: 4 | O19: 5 | P19: 6 | Q19: 7 | R19: 8 | S19: 9 | T19: SDN-1 SAKA MANGKAHAI | V19: SDN-3 ANJIR KALAMPAN | W19: 9 | X19: 8 | Y19: 7 | Z19: 6 | AA19: 5 | AB19: 4 | AC19: 3 | AD19: 2 | AE19: 1 | AF19: 2 | AG19: 3 | AH19: 4 | AI19: 5 | AJ19: 6 | AK19: 7 | AL19: 8 | AM19: 9 | AN19: SDN-1 SAKA MANGKAHAI | AP19: SDN-3 ANJIR KALAMPAN | AQ19: 9 | AR19: 8 | AS19: 7 | AT19: 6 | AU19: 5 | AV19: 4 | AW19: 3 | AX19: 2 | AY19: 1 | AZ19: 2 | BA19: 3 | BB19: 4 | BC19: 5 | BD19: 6 | BE19: 7 | BF19: 8 | BG19: 9 | BH19: SDN-1 SAKA MANGKAHAI
B20: SDN-3 ANJIR KALAMPAN | C20: 9 | D20: 8 | E20: 7 | F20: 6 | G20: 5 | H20: 4 | I20: 3 | J20: 2 | K20: 1 | L20: 2 | M20: 3 | N20: 4 | O20: 5 | P20: 6 | Q20: 7 | R20: 8 | S20: 9 | T20: SDN-2 SAKA MANGKAHAI | V20: SDN-3 ANJIR KALAMPAN | W20: 9 | X20: 8 | Y20: 7 | Z20: 6 | AA20: 5 | AB20: 4 | AC20: 3 | AD20: 2 | AE20: 1 | AF20: 2 | AG20: 3 | AH20: 4 | AI20: 5 | AJ20: 6 | AK20: 7 | AL20: 8 | AM20: 9 | AN20: SDN-2 SAKA MANGKAHAI | AP20: SDN-3 ANJIR KALAMPAN | AQ20: 9 | AR20: 8 | AS20: 7 | AT20: 6 | AU20: 5 | AV20: 4 | AW20: 3 | AX20: 2 | AY20: 1 | AZ20: 2 | BA20: 3 | BB20: 4 | BC20: 5 | BD20: 6 | BE20: 7 | BF20: 8 | BG20: 9 | BH20: SDN-2 SAKA MANGKAHAI
B21: SDN-3 ANJIR KALAMPAN | C21: 9 | D21: 8 | E21: 7 | F21: 6 | G21: 5 | H21: 4 | I21: 3 | J21: 2 | K21: 1 | L21: 2 | M21: 3 | N21: 4 | O21: 5 | P21: 6 | Q21: 7 | R21: 8 | S21: 9 | T21: SDN-2 MANDOMAI | V21: SDN-3 ANJIR KALAMPAN | W21: 9 | X21: 8 | Y21: 7 | Z21: 6 | AA21: 5 | AB21: 4 | AC21: 3 | AD21: 2 | AE21: 1 | AF21: 2 | AG21: 3 | AH21: 4 | AI21: 5 | AJ21: 6 | AK21: 7 | AL21: 8 | AM21: 9 | AN21: SDN-2 MANDOMAI | AP21: SDN-3 ANJIR KALAMPAN | AQ21: 9 | AR21: 8 | AS21: 7 | AT21: 6 | AU21: 5 | AV21: 4 | AW21: 3 | AX21: 2 | AY21: 1 | AZ21: 2 | BA21: 3 | BB21: 4 | BC21: 5 | BD21: 6 | BE21: 7 | BF21: 8 | BG21: 9 | BH21: SDN-2 MANDOMAI
B22: SDN-3 ANJIR KALAMPAN | C22: 9 | D22: 8 | E22: 7 | F22: 6 | G22: 5 | H22: 4 | I22: 3 | J22: 2 | K22: 1 | L22: 2 | M22: 3 | N22: 4 | O22: 5 | P22: 6 | Q22: 7 | R22: 8 | S22: 9 | T22: SDN-3 MANDOMAI | V22: SDN-3 ANJIR KALAMPAN | W22: 9 | X22: 8 | Y22: 7 | Z22: 6 | AA22: 5 | AB22: 4 | AC22: 3 | AD22: 2 | AE22: 1 | AF22: 2 | AG22: 3 | AH22: 4 | AI22: 5 | AJ22: 6 | AK22: 7 | AL22: 8 | AM22: 9 | AN22: SDN-3 MANDOMAI | AP22: SDN-3 ANJIR KALAMPAN | AQ22: 9 | AR22: 8 | AS22: 7 | AT22: 6 | AU22: 5 | AV22: 4 | AW22: 3 | AX22: 2 | AY22: 1 | AZ22: 2 | BA22: 3 | BB22: 4 | BC22: 5 | BD22: 6 | BE22: 7 | BF22: 8 | BG22: 9 | BH22: SDN-3 MANDOMAI
B23: SDN-3 ANJIR KALAMPAN | C23: 9 | D23: 8 | E23: 7 | F23: 6 | G23: 5 | H23: 4 | I23: 3 | J23: 2 | K23: 1 | L23: 2 | M23: 3 | N23: 4 | O23: 5 | P23: 6 | Q23: 7 | R23: 8 | S23: 9 | T23: SDN-4 MANDOMAI | V23: SDN-3 ANJIR KALAMPAN | W23: 9 | X23: 8 | Y23: 7 | Z23: 6 | AA23: 5 | AB23: 4 | AC23: 3 | AD23: 2 | AE23: 1 | AF23: 2 | AG23: 3 | AH23: 4 | AI23: 5 | AJ23: 6 | AK23: 7 | AL23: 8 | AM23: 9 | AN23: SDN-4 MANDOMAI | AP23: SDN-3 ANJIR KALAMPAN | AQ23: 9 | AR23: 8 | AS23: 7 | AT23: 6 | AU23: 5 | AV23: 4 | AW23: 3 | AX23: 2 | AY23: 1 | AZ23: 2 | BA23: 3 | BB23: 4 | BC23: 5 | BD23: 6 | BE23: 7 | BF23: 8 | BG23: 9 | BH23: SDN-4 MANDOMAI
B24: SDN-3 ANJIR KALAMPAN | C24: 9 | D24: 8 | E24: 7 | F24: 6 | G24: 5 | H24: 4 | I24: 3 | J24: 2 | K24: 1 | L24: 2 | M24: 3 | N24: 4 | O24: 5 | P24: 6 | Q24: 7 | R24: 8 | S24: 9 | T24: SDN-1 PANTAI | V24: SDN-3 ANJIR KALAMPAN | W24: 9 | X24: 8 | Y24: 7 | Z24: 6 | AA24: 5 | AB24: 4 | AC24: 3 | AD24: 2 | AE24: 1 | AF24: 2 | AG24: 3 | AH24: 4 | AI24: 5 | AJ24: 6 | AK24: 7 | AL24: 8 | AM24: 9 | AN24: SDN-1 PANTAI | AP24: SDN-3 ANJIR KALAMPAN | AQ24: 9 | AR24: 8 | AS24: 7 | AT24: 6 | AU24: 5 | AV24: 4 | AW24: 3 | AX24: 2 | AY24: 1 | AZ24: 2 | BA24: 3 | BB24: 4 | BC24: 5 | BD24: 6 | BE24: 7 | BF24: 8 | BG24: 9 | BH24: SDN-1 PANTAI
B25: SDN-3 ANJIR KALAMPAN | C25: 9 | D25: 8 | E25: 7 | F25: 6 | G25: 5 | H25: 4 | I25: 3 | J25: 2 | K25: 1 | L25: 2 | M25: 3 | N25: 4 | O25: 5 | P25: 6 | Q25: 7 | R25: 8 | S25: 9 | T25: SDN-2 PANTAI | V25: SDN-3 ANJIR KALAMPAN | W25: 9 | X25: 8 | Y25: 7 | Z25: 6 | AA25: 5 | AB25: 4 | AC25: 3 | AD25: 2 | AE25: 1 | AF25: 2 | AG25: 3 | AH25: 4 | AI25: 5 | AJ25: 6 | AK25: 7 | AL25: 8 | AM25: 9 | AN25: SDN-2 PANTAI | AP25: SDN-3 ANJIR KALAMPAN | AQ25: 9 | AR25: 8 | AS25: 7 | AT25: 6 | AU25: 5 | AV25: 4 | AW25: 3 | AX25: 2 | AY25: 1 | AZ25: 2 | BA25: 3 | BB25: 4 | BC25: 5 | BD25: 6 | BE25: 7 | BF25: 8 | BG25: 9 | BH25: SDN-2 PANTAI
... B109: SDN-2 SEI KAYU | C109: 9 | D109: 8 | E109: 7 | F109: 6 | G109: 5 | H109: 4 | I109: 3 | J109: 2 | K109: 1 | L109: 2 | M109: 3 | N109: 4 | O109: 5 | P109: 6 | Q109: 7 | R109: 8 | S109: 9 | T109: SDN-1 SEI DUSUN | V109: SDN-2 SEI KAYU | W109: 9 | X109: 8 | Y109: 7 | Z109: 6 | AA109: 5 | AB109: 4 | AC109: 3 | AD109: 2 | AE109: 1 | AF109: 2 | AG109: 3 | AH109: 4 | AI109: 5 | AJ109: 6 | AK109: 7 | AL109: 8 | AM109: 9 | AN109: SDN-1 SEI DUSUN | AP109: SDN-2 SEI KAYU | AQ109: 9 | AR109: 8 | AS109: 7 | AT109: 6 | AU109: 5 | AV109: 4 | AW109: 3 | AX109: 2 | AY109: 1 | AZ109: 2 | BA109: 3 | BB109: 4 | BC109: 5 | BD109: 6 | BE109: 7 | BF109: 8 | BG109: 9 | BH109: SDN-1 SEI DUSUN

Sheet LOKASI GEDUNG
B1: LOKASI GEDUNG | V1: LOKASI GEDUNG | AP1: LOKASI GEDUNG
B2: PENGAWAS SEKOLAH DASAR KAPUAS BARAT (JHON) | V2: KEPALA BIDANG PENGAWASAN SEKOLAH DASAR DISDIK KAPUAS (JEFRI) | AP2: KOMISI IV DPRD KAB. KAPUAS
B3: SEKOLAH UTAMA | C3: KRITERIA NILAI | T3: SEKOLAH PEMBANDING | V3: SEKOLAH UTAMA | W3: KRITERIA NILAI | AN3: SEKOLAH PEMBANDING | AP3: SEKOLAH UTAMA | AQ3: KRITERIA NILAI | BH3: SEKOLAH PEMBANDING
C4: 9 | D4: 8 | E4: 7 | F4: 6 | G4: 5 | H4: 4 | I4: 3 | J4: 2 | K4: 1 | L4: 2 | M4: 3 | N4: 4 | O4: 5 | P4: 6 | Q4: 7 | R4: 8 | S4: 9 | W4: 9 | X4: 8 | Y4: 7 | Z4: 6 | AA4: 5 | AB4: 4 | AC4: 3 | AD4: 2 | AE4: 1 | AF4: 2 | AG4: 3 | AH4: 4 | AI4: 5 | AJ4: 6 | AK4: 7 | AL4: 8 | AM4: 9 | AQ4: 9 | AR4: 8 | AS4: 7 | AT4: 6 | AU4: 5 | AV4: 4 | AW4: 3 | AX4: 2 | AY4: 1 | AZ4: 2 | BA4: 3 | BB4: 4 | BC4: 5 | BD4: 6 | BE4: 7 | BF4: 8 | BG4: 9
B5: SDN-2 ANJIR KALAMPAN | C5: 9 | D5: 8 | E5: 7 | F5: 6 | G5: 5 | H5: 4 | I5: 3 | J5: 2 | K5: 1 | L5: 2 | M5: 3 | N5: 4 | O5: 5 | P5: 6 | Q5: 7 | R5: 8 | S5: 9 | T5: SDN-3 ANJIR KALAMPAN | V5: SDN-2 ANJIR KALAMPAN | W5: 9 | X5: 8 | Y5: 7 | Z5: 6 | AA5: 5 | AB5: 4 | AC5: 3 | AD5: 2 | AE5: 1 | AF5: 2 | AG5: 3 | AH5: 4 | AI5: 5 | AJ5: 6 | AK5: 7 | AL5: 8 | AM5: 9 | AN5: SDN-3 ANJIR KALAMPAN | AP5: SDN-2 ANJIR KALAMPAN | AQ5: 9 | AR5: 8 | AS5: 7 | AT5: 6 | AU5: 5 | AV5: 4 | AW5: 3 | AX5: 2 | AY5: 1 | AZ5: 2 | BA5: 3 | BB5: 4 | BC5: 5 | BD5: 6 | BE5: 7 | BF5: 8 | BG5: 9 | BH5: SDN-3 ANJIR KALAMPAN | BJ5: PANDUAN PENGISIAN | BN5: CONDONG KE A | BV5: NETRAL | BW5: CONDONG KE B
B6: SDN-2 ANJIR KALAMPAN | C6: 9 | D6: 8 | E6: 7 | F6: 6 | G6: 5 | H6: 4 | I6: 3 | J6: 2 | K6: 1 | L6: 2 | M6: 3 | N6: 4 | O6: 5 | P6: 6 | Q6: 7 | R6: 8 | S6: 9 | T6: SDN-1 SAKA MANGKAHAI | V6: SDN-2 ANJIR KALAMPAN | W6: 9 | X6: 8 | Y6: 7 | Z6: 6 | AA6: 5 | AB6: 4 | AC6: 3 | AD6: 2 | AE6: 1 | AF6: 2 | AG6: 3 | AH6: 4 | AI6: 5 | AJ6: 6 | AK6: 7 | AL6: 8 | AM6: 9 | AN6: SDN-1 SAKA MANGKAHAI | AP6: SDN-2 ANJIR KALAMPAN | AQ6: 9 | AR6: 8 | AS6: 7 | AT6: 6 | AU6: 5 | AV6: 4 | AW6: 3 | AX6: 2 | AY6: 1 | AZ6: 2 | BA6: 3 | BB6: 4 | BC6: 5 | BD6: 6 | BE6: 7 | BF6: 8 | BG6: 9 | BH6: SDN-1 SAKA MANGKAHAI | BJ6: TINGKAT KEPENTINGAN | BK6: DEFINISI | BM6: PILIHAN A | BN6: 9 | BO6: 8 | BP6: 7 | BQ6: 6 | BR6: 5 | BS6: 4 | BT6: 3 | BU6: 2 | BV6: 1 | BW6: 2 | BX6: 3 | BY6: 4 | BZ6: 5 | CA6: 6 | CB6: 7 | CC6: 8 | CD6: 9 | CE6: PILIHAN B
B7: SDN-2 ANJIR KALAMPAN | C7: 9 | D7: 8 | E7: 7 | F7: 6 | G7: 5 | H7: 4 | I7: 3 | J7: 2 | K7: 1 | L7: 2 | M7: 3 | N7: 4 | O7: 5 | P7: 6 | Q7: 7 | R7: 8 | S7: 9 | T7: SDN-2 SAKA MANGKAHAI | V7: SDN-2 ANJIR KALAMPAN | W7: 9 | X7: 8 | Y7: 7 | Z7: 6 | AA7: 5 | AB7: 4 | AC7: 3 | AD7: 2 | AE7: 1 | AF7: 2 | AG7: 3 | AH7: 4 | AI7: 5 | AJ7: 6 | AK7: 7 | AL7: 8 | AM7: 9 | AN7: SDN-2 SAKA MANGKAHAI | AP7: SDN-2 ANJIR KALAMPAN | AQ7: 9 | AR7: 8 | AS7: 7 | AT7: 6 | AU7: 5 | AV7: 4 | AW7: 3 | AX7: 2 | AY7: 1 | AZ7: 2 | BA7: 3 | BB7: 4 | BC7: 5 | BD7: 6 | BE7: 7 | BF7: 8 | BG7: 9 | BH7: SDN-2 SAKA MANGKAHAI | BJ7: 1 | BK7: KEDUA ELEMEN SAMA PENTING
B8: SDN-2 ANJIR KALAMPAN | C8: 9 | D8: 8 | E8: 7 | F8: 6 | G8: 5 | H8: 4 | I8: 3 | J8: 2 | K8: 1 | L8: 2 | M8: 3 | N8: 4 | O8: 5 | P8: 6 | Q8: 7 | R8: 8 | S8: 9 | T8: SDN-2 MANDOMAI | V8: SDN-2 ANJIR KALAMPAN | W8: 9 | X8: 8 | Y8: 7 | Z8: 6 | AA8: 5 | AB8: 4 | AC8: 3 | AD8: 2 | AE8: 1 | AF8: 2 | AG8: 3 | AH8: 4 | AI8: 5 | AJ8: 6 | AK8: 7 | AL8: 8 | AM8: 9 | AN8: SDN-2 MANDOMAI | AP8: SDN-2 ANJIR KALAMPAN | AQ8: 9 | AR8: 8 | AS8: 7 | AT8: 6 | AU8: 5 | AV8: 4 | AW8: 3 | AX8: 2 | AY8: 1 | AZ8: 2 | BA8: 3 | BB8: 4 | BC8: 5 | BD8: 6 | BE8: 7 | BF8: 8 | BG8: 9 | BH8: SDN-2 MANDOMAI | BJ8: 3 | BK8: ELEMEN YANG SATU SEDIKIT LEBIH PENTING DARI YANG LAIN
B9: SDN-2 ANJIR KALAMPAN | C9: 9 | D9: 8 | E9: 7 | F9: 6 | G9: 5 | H9: 4 | I9: 3 | J9: 2 | K9: 1 | L9: 2 | M9: 3 | N9: 4 | O9: 5 | P9: 6 | Q9: 7 | R9: 8 | S9: 9 | T9: SDN-3 MANDOMAI | V9: SDN-2 ANJIR KALAMPAN | W9: 9 | X9: 8 | Y9: 7 | Z9: 6 | AA9: 5 | AB9: 4 | AC9: 3 | AD9: 2 | AE9: 1 | AF9: 2 | AG9: 3 | AH9: 4 | AI9: 5 | AJ9: 6 | AK9: 7 | AL9: 8 | AM9: 9 | AN9: SDN-3 MANDOMAI | AP9: SDN-2 ANJIR KALAMPAN | AQ9: 9 | AR9: 8 | AS9: 7 | AT9: 6 | AU9: 5 | AV9: 4 | AW9: 3 | AX9: 2 | AY9: 1 | AZ9: 2 | BA9: 3 | BB9: 4 | BC9: 5 | BD9: 6 | BE9: 7 | BF9: 8 | BG9: 9 | BH9: SDN-3 MANDOMAI | BJ9: 5 | BK9: ELEMEN YANG SATU LEBIH PENTING DARI YANG LAIN
B10: SDN-2 ANJIR KALAMPAN | C10: 9 | D10: 8 | E10: 7 | F10: 6 | G10: 5 | H10: 4 | I10: 3 | J10: 2 | K10: 1 | L10: 2 | M10: 3 | N10: 4 | O10: 5 | P10: 6 | Q10: 7 | R10: 8 | S10: 9 | T10: SDN-4 MANDOMAI | V10: SDN-2 ANJIR KALAMPAN | W10: 9 | X10: 8 | Y10: 7 | Z10: 6 | AA10: 5 | AB10: 4 | AC10: 3 | AD10: 2 | AE10: 1 | AF10: 2 | AG10: 3 | AH10: 4 | AI10: 5 | AJ10: 6 | AK10: 7 | AL10: 8 | AM10: 9 | AN10: SDN-4 MANDOMAI | AP10: SDN-2 ANJIR KALAMPAN | AQ10: 9 | AR10: 8 | AS10: 7 | AT10: 6 | AU10: 5 | AV10: 4 | AW10: 3 | AX10: 2 | AY10: 1 | AZ10: 2 | BA10: 3 | BB10: 4 | BC10: 5 | BD10: 6 | BE10: 7 | BF10: 8 | BG10: 9 | BH10: SDN-4 MANDOMAI | BJ10: 7 | BK10: ELEMEN YANG SATU SANGAT PENTING DARI YANG LAIN
B11: SDN-2 ANJIR KALAMPAN | C11: 9 | D11: 8 | E11: 7 | F11: 6 | G11: 5 | H11: 4 | I11: 3 | J11: 2 | K11: 1 | L11: 2 | M11: 3 | N11: 4 | O11: 5 | P11: 6 | Q11: 7 | R11: 8 | S11: 9 | T11: SDN-1 PANTAI | V11: SDN-2 ANJIR KALAMPAN | W11: 9 | X11: 8 | Y11: 7 | Z11: 6 | AA11: 5 | AB11: 4 | AC11: 3 | AD11: 2 | AE11: 1 | AF11: 2 | AG11: 3 | AH11: 4 | AI11: 5 | AJ11: 6 | AK11: 7 | AL11: 8 | AM11: 9 | AN11: SDN-1 PANTAI | AP11: SDN-2 ANJIR KALAMPAN | AQ11: 9 | AR11: 8 | AS11: 7 | AT11: 6 | AU11: 5 | AV11: 4 | AW11: 3 | AX11: 2 | AY11: 1 | AZ11: 2 | BA11: 3 | BB11: 4 | BC11: 5 | BD11: 6 | BE11: 7 | BF11: 8 | BG11: 9 | BH11: SDN-1 PANTAI | BJ11: 9 | BK11: ELEMEN YANG SATU MUTLAK LEBIH PENTING DARI YANG LAIN
B12: SDN-2 ANJIR KALAMPAN | C12: 9 | D12: 8 | E12: 7 | F12: 6 | G12: 5 | H12: 4 | I12: 3 | J12: 2 | K12: 1 | L12: 2 | M12: 3 | N12: 4 | O12: 5 | P12: 6 | Q12: 7 | R12: 8 | S12: 9 | T12: SDN-2 PANTAI | V12: SDN-2 ANJIR KALAMPAN | W12: 9 | X12: 8 | Y12: 7 | Z12: 6 | AA12: 5 | AB12: 4 | AC12: 3 | AD12: 2 | AE12: 1 | AF12: 2 | AG12: 3 | AH12: 4 | AI12: 5 | AJ12: 6 | AK12: 7 | AL12: 8 | AM12: 9 | AN12: SDN-2 PANTAI | AP12: SDN-2 ANJIR KALAMPAN | AQ12: 9 | AR12: 8 | AS12: 7 | AT12: 6 | AU12: 5 | AV12: 4 | AW12: 3 | AX12: 2 | AY12: 1 | AZ12: 2 | BA12: 3 | BB12: 4 | BC12: 5 | BD12: 6 | BE12: 7 | BF12: 8 | BG12: 9 | BH12: SDN-2 PANTAI | BJ12: 2,4,6,8 | BK12: NILAI KOMPROMI (NILAI TENGAH ANTARA DUA PERBANDINGAN)
B13: SDN-2 ANJIR KALAMPAN | C13: 9 | D13: 8 | E13: 7 | F13: 6 | G13: 5 | H13: 4 | I13: 3 | J13: 2 | K13: 1 | L13: 2 | M13: 3 | N13: 4 | O13: 5 | P13: 6 | Q13: 7 | R13: 8 | S13: 9 | T13: SDN-1 BASUTA RAYA | V13: SDN-2 ANJIR KALAMPAN | W13: 9 | X13: 8 | Y13: 7 | Z13: 6 | AA13: 5 | AB13: 4 | AC13: 3 | AD13: 2 | AE13: 1 | AF13: 2 | AG13: 3 | AH13: 4 | AI13: 5 | AJ13: 6 | AK13: 7 | AL13: 8 | AM13: 9 | AN13: SDN-1 BASUTA RAYA | AP13: SDN-2 ANJIR KALAMPAN | AQ13: 9 | AR13: 8 | AS13: 7 | AT13: 6 | AU13: 5 | AV13: 4 | AW13: 3 | AX13: 2 | AY13: 1 | AZ13: 2 | BA13: 3 | BB13: 4 | BC13: 5 | BD13: 6 | BE13: 7 | BF13: 8 | BG13: 9 | BH13: SDN-1 BASUTA RAYA
B14: SDN-2 ANJIR KALAMPAN | C14: 9 | D14: 8 | E14: 7 | F14: 6 | G14: 5 | H14: 4 | I14: 3 | J14: 2 | K14: 1 | L14: 2 | M14: 3 | N14: 4 | O14: 5 | P14: 6 | Q14: 7 | R14: 8 | S14: 9 | T14: SDN-1 SEI PITUNG | V14: SDN-2 ANJIR KALAMPAN | W14: 9 | X14: 8 | Y14: 7 | Z14: 6 | AA14: 5 | AB14: 4 | AC14: 3 | AD14: 2 | AE14: 1 | AF14: 2 | AG14: 3 | AH14: 4 | AI14: 5 | AJ14: 6 | AK14: 7 | AL14: 8 | AM14: 9 | AN14: SDN-1 SEI PITUNG | AP14: SDN-2 ANJIR KALAMPAN | AQ14: 9 | AR14: 8 | AS14: 7 | AT14: 6 | AU14: 5 | AV14: 4 | AW14: 3 | AX14: 2 | AY14: 1 | AZ14: 2 | BA14: 3 | BB14: 4 | BC14: 5 | BD14: 6 | BE14: 7 | BF14: 8 | BG14: 9 | BH14: SDN-1 SEI PITUNG
B15: SDN-2 ANJIR KALAMPAN | C15: 9 | D15: 8 | E15: 7 | F15: 6 | G15: 5 | H15: 4 | I15: 3 | J15: 2 | K15: 1 | L15: 2 | M15: 3 | N15: 4 | O15: 5 | P15: 6 | Q15: 7 | R15: 8 | S15: 9 | T15: SDN-1 PENDA KATAPI | V15: SDN-2 ANJIR KALAMPAN | W15: 9 | X15: 8 | Y15: 7 | Z15: 6 | AA15: 5 | AB15: 4 | AC15: 3 | AD15: 2 | AE15: 1 | AF15: 2 | AG15: 3 | AH15: 4 | AI15: 5 | AJ15: 6 | AK15: 7 | AL15: 8 | AM15: 9 | AN15: SDN-1 PENDA KATAPI | AP15: SDN-2 ANJIR KALAMPAN | AQ15: 9 | AR15: 8 | AS15: 7 | AT15: 6 | AU15: 5 | AV15: 4 | AW15: 3 | AX15: 2 | AY15: 1 | AZ15: 2 | BA15: 3 | BB15: 4 | BC15: 5 | BD15: 6 | BE15: 7 | BF15: 8 | BG15: 9 | BH15: SDN-1 PENDA KATAPI
B16: SDN-2 ANJIR KALAMPAN | C16: 9 | D16: 8 | E16: 7 | F16: 6 | G16: 5 | H16: 4 | I16: 3 | J16: 2 | K16: 1 | L16: 2 | M16: 3 | N16: 4 | O16: 5 | P16: 6 | Q16: 7 | R16: 8 | S16: 9 | T16: SDN-1 SEI KAYU | V16: SDN-2 ANJIR KALAMPAN | W16: 9 | X16: 8 | Y16: 7 | Z16: 6 | AA16: 5 | AB16: 4 | AC16: 3 | AD16: 2 | AE16: 1 | AF16: 2 | AG16: 3 | AH16: 4 | AI16: 5 | AJ16: 6 | AK16: 7 | AL16: 8 | AM16: 9 | AN16: SDN-1 SEI KAYU | AP16: SDN-2 ANJIR KALAMPAN | AQ16: 9 | AR16: 8 | AS16: 7 | AT16: 6 | AU16: 5 | AV16: 4 | AW16: 3 | AX16: 2 | AY16: 1 | AZ16: 2 | BA16: 3 | BB16: 4 | BC16: 5 | BD16: 6 | BE16: 7 | BF16: 8 | BG16: 9 | BH16: SDN-1 SEI KAYU
B17: SDN-2 ANJIR KALAMPAN | C17: 9 | D17: 8 | E17: 7 | F17: 6 | G17: 5 | H17: 4 | I17: 3 | J17: 2 | K17: 1 | L17: 2 | M17: 3 | N17: 4 | O17: 5 | P17: 6 | Q17: 7 | R17: 8 | S17: 9 | T17: SDN-2 SEI KAYU | V17: SDN-2 ANJIR KALAMPAN | W17: 9 | X17: 8 | Y17: 7 | Z17: 6 | AA17: 5 | AB17: 4 | AC17: 3 | AD17: 2 | AE17: 1 | AF17: 2 | AG17: 3 | AH17: 4 | AI17: 5 | AJ17: 6 | AK17: 7 | AL17: 8 | AM17: 9 | AN17: SDN-2 SEI KAYU | AP17: SDN-2 ANJIR KALAMPAN | AQ17: 9 | AR17: 8 | AS17: 7 | AT17: 6 | AU17: 5 | AV17: 4 | AW17: 3 | AX17: 2 | AY17: 1 | AZ17: 2 | BA17: 3 | BB17: 4 | BC17: 5 | BD17: 6 | BE17: 7 | BF17: 8 | BG17: 9 | BH17: SDN-2 SEI KAYU
B18: SDN-2 ANJIR KALAMPAN | C18: 9 | D18: 8 | E18: 7 | F18: 6 | G18: 5 | H18: 4 | I18: 3 | J18: 2 | K18: 1 | L18: 2 | M18: 3 | N18: 4 | O18: 5 | P18: 6 | Q18: 7 | R18: 8 | S18: 9 | T18: SDN-1 SEI DUSUN | V18: SDN-2 ANJIR KALAMPAN | W18: 9 | X18: 8 | Y18: 7 | Z18: 6 | AA18: 5 | AB18: 4 | AC18: 3 | AD18: 2 | AE18: 1 | AF18: 2 | AG18: 3 | AH18: 4 | AI18: 5 | AJ18: 6 | AK18: 7 | AL18: 8 | AM18: 9 | AN18: SDN-1 SEI DUSUN | AP18: SDN-2 ANJIR KALAMPAN | AQ18: 9 | AR18: 8 | AS18: 7 | AT18: 6 | AU18: 5 | AV18: 4 | AW18: 3 | AX18: 2 | AY18: 1 | AZ18: 2 | BA18: 3 | BB18: 4 | BC18: 5 | BD18: 6 | BE18: 7 | BF18: 8 | BG18: 9 | BH18: SDN-1 SEI DUSUN
B19: SDN-3 ANJIR KALAMPAN | C19: 9 | D19: 8 | E19: 7 | F19: 6 | G19: 5 | H19: 4 | I19: 3 | J19: 2 | K19: 1 | L19: 2 | M19: 3 | N19: 4 | O19: 5 | P19: 6 | Q19: 7 | R19: 8 | S19: 9 | T19: SDN-1 SAKA MANGKAHAI | V19: SDN-3 ANJIR KALAMPAN | W19: 9 | X19: 8 | Y19: 7 | Z19: 6 | AA19: 5 | AB19: 4 | AC19: 3 | AD19: 2 | AE19: 1 | AF19: 2 | AG19: 3 | AH19: 4 | AI19: 5 | AJ19: 6 | AK19: 7 | AL19: 8 | AM19: 9 | AN19: SDN-1 SAKA MANGKAHAI | AP19: SDN-3 ANJIR KALAMPAN | AQ19: 9 | AR19: 8 | AS19: 7 | AT19: 6 | AU19: 5 | AV19: 4 | AW19: 3 | AX19: 2 | AY19: 1 | AZ19: 2 | BA19: 3 | BB19: 4 | BC19: 5 | BD19: 6 | BE19: 7 | BF19: 8 | BG19: 9 | BH19: SDN-1 SAKA MANGKAHAI
B20: SDN-3 ANJIR KALAMPAN | C20: 9 | D20: 8 | E20: 7 | F20: 6 | G20: 5 | H20: 4 | I20: 3 | J20: 2 | K20: 1 | L20: 2 | M20: 3 | N20: 4 | O20: 5 | P20: 6 | Q20: 7 | R20: 8 | S20: 9 | T20: SDN-2 SAKA MANGKAHAI | V20: SDN-3 ANJIR KALAMPAN | W20: 9 | X20: 8 | Y20: 7 | Z20: 6 | AA20: 5 | AB20: 4 | AC20: 3 | AD20: 2 | AE20: 1 | AF20: 2 | AG20: 3 | AH20: 4 | AI20: 5 | AJ20: 6 | AK20: 7 | AL20: 8 | AM20: 9 | AN20: SDN-2 SAKA MANGKAHAI | AP20: SDN-3 ANJIR KALAMPAN | AQ20: 9 | AR20: 8 | AS20: 7 | AT20: 6 | AU20: 5 | AV20: 4 | AW20: 3 | AX20: 2 | AY20: 1 | AZ20: 2 | BA20: 3 | BB20: 4 | BC20: 5 | BD20: 6 | BE20: 7 | BF20: 8 | BG20: 9 | BH20: SDN-2 SAKA MANGKAHAI
B21: SDN-3 ANJIR KALAMPAN | C21: 9 | D21: 8 | E21: 7 | F21: 6 | G21: 5 | H21: 4 | I21: 3 | J21: 2 | K21: 1 | L21: 2 | M21: 3 | N21: 4 | O21: 5 | P21: 6 | Q21: 7 | R21: 8 | S21: 9 | T21: SDN-2 MANDOMAI | V21: SDN-3 ANJIR KALAMPAN | W21: 9 | X21: 8 | Y21: 7 | Z21: 6 | AA21: 5 | AB21: 4 | AC21: 3 | AD21: 2 | AE21: 1 | AF21: 2 | AG21: 3 | AH21: 4 | AI21: 5 | AJ21: 6 | AK21: 7 | AL21: 8 | AM21: 9 | AN21: SDN-2 MANDOMAI | AP21: SDN-3 ANJIR KALAMPAN | AQ21: 9 | AR21: 8 | AS21: 7 | AT21: 6 | AU21: 5 | AV21: 4 | AW21: 3 | AX21: 2 | AY21: 1 | AZ21: 2 | BA21: 3 | BB21: 4 | BC21: 5 | BD21: 6 | BE21: 7 | BF21: 8 | BG21: 9 | BH21: SDN-2 MANDOMAI
B22: SDN-3 ANJIR KALAMPAN | C22: 9 | D22: 8 | E22: 7 | F22: 6 | G22: 5 | H22: 4 | I22: 3 | J22: 2 | K22: 1 | L22: 2 | M22: 3 | N22: 4 | O22: 5 | P22: 6 | Q22: 7 | R22: 8 | S22: 9 | T22: SDN-3 MANDOMAI | V22: SDN-3 ANJIR KALAMPAN | W22: 9 | X22: 8 | Y22: 7 | Z22: 6 | AA22: 5 | AB22: 4 | AC22: 3 | AD22: 2 | AE22: 1 | AF22: 2 | AG22: 3 | AH22: 4 | AI22: 5 | AJ22: 6 | AK22: 7 | AL22: 8 | AM22: 9 | AN22: SDN-3 MANDOMAI | AP22: SDN-3 ANJIR KALAMPAN | AQ22: 9 | AR22: 8 | AS22: 7 | AT22: 6 | AU22: 5 | AV22: 4 | AW22: 3 | AX22: 2 | AY22: 1 | AZ22: 2 | BA22: 3 | BB22: 4 | BC22: 5 | BD22: 6 | BE22: 7 | BF22: 8 | BG22: 9 | BH22: SDN-3 MANDOMAI
B23: SDN-3 ANJIR KALAMPAN | C23: 9 | D23: 8 | E23: 7 | F23: 6 | G23: 5 | H23: 4 | I23: 3 | J23: 2 | K23: 1 | L23: 2 | M23: 3 | N23: 4 | O23: 5 | P23: 6 | Q23: 7 | R23: 8 | S23: 9 | T23: SDN-4 MANDOMAI | V23: SDN-3 ANJIR KALAMPAN | W23: 9 | X23: 8 | Y23: 7 | Z23: 6 | AA23: 5 | AB23: 4 | AC23: 3 | AD23: 2 | AE23: 1 | AF23: 2 | AG23: 3 | AH23: 4 | AI23: 5 | AJ23: 6 | AK23: 7 | AL23: 8 | AM23: 9 | AN23: SDN-4 MANDOMAI | AP23: SDN-3 ANJIR KALAMPAN | AQ23: 9 | AR23: 8 | AS23: 7 | AT23: 6 | AU23: 5 | AV23: 4 | AW23: 3 | AX23: 2 | AY23: 1 | AZ23: 2 | BA23: 3 | BB23: 4 | BC23: 5 | BD23: 6 | BE23: 7 | BF23: 8 | BG23: 9 | BH23: SDN-4 MANDOMAI
B24: SDN-3 ANJIR KALAMPAN | C24: 9 | D24: 8 | E24: 7 | F24: 6 | G24: 5 | H24: 4 | I24: 3 | J24: 2 | K24: 1 | L24: 2 | M24: 3 | N24: 4 | O24: 5 | P24: 6 | Q24: 7 | R24: 8 | S24: 9 | T24: SDN-1 PANTAI | V24: SDN-3 ANJIR KALAMPAN | W24: 9 | X24: 8 | Y24: 7 | Z24: 6 | AA24: 5 | AB24: 4 | AC24: 3 | AD24: 2 | AE24: 1 | AF24: 2 | AG24: 3 | AH24: 4 | AI24: 5 | AJ24: 6 | AK24: 7 | AL24: 8 | AM24: 9 | AN24: SDN-1 PANTAI | AP24: SDN-3 ANJIR KALAMPAN | AQ24: 9 | AR24: 8 | AS24: 7 | AT24: 6 | AU24: 5 | AV24: 4 | AW24: 3 | AX24: 2 | AY24: 1 | AZ24: 2 | BA24: 3 | BB24: 4 | BC24: 5 | BD24: 6 | BE24: 7 | BF24: 8 | BG24: 9 | BH24: SDN-1 PANTAI
... B109: SDN-2 SEI KAYU | C109: 9 | D109: 8 | E109: 7 | F109: 6 | G109: 5 | H109: 4 | I109: 3 | J109: 2 | K109: 1 | L109: 2 | M109: 3 | N109: 4 | O109: 5 | P109: 6 | Q109: 7 | R109: 8 | S109: 9 | T109: SDN-1 SEI DUSUN | V109: SDN-2 SEI KAYU | W109: 9 | X109: 8 | Y109: 7 | Z109: 6 | AA109: 5 | AB109: 4 | AC109: 3 | AD109: 2 | AE109: 1 | AF109: 2 | AG109: 3 | AH109: 4 | AI109: 5 | AJ109: 6 | AK109: 7 | AL109: 8 | AM109: 9 | AN109: SDN-1 SEI DUSUN | AP109: SDN-2 SEI KAYU | AQ109: 9 | AR109: 8 | AS109: 7 | AT109: 6 | AU109: 5 | AV109: 4 | AW109: 3 | AX109: 2 | AY109: 1 | AZ109: 2 | BA109: 3 | BB109: 4 | BC109: 5 | BD109: 6 | BE109: 7 | BF109: 8 | BG109: 9 | BH109: SDN-1 SEI DUSUN

Sheet USIA BANGUNAN
B1: USIA BANGUNAN | V1: USIA BANGUNAN | AP1: USIA BANGUNAN
B2: PENGAWAS SEKOLAH DASAR KAPUAS BARAT (JHON) | V2: KEPALA BIDANG PENGAWASAN SEKOLAH DASAR DISDIK KAPUAS (JEFRI) | AP2: KOMISI IV DPRD KAB. KAPUAS
B3: SEKOLAH UTAMA | C3: KRITERIA NILAI | T3: SEKOLAH PEMBANDING | V3: SEKOLAH UTAMA | W3: KRITERIA NILAI | AN3: SEKOLAH PEMBANDING | AP3: SEKOLAH UTAMA | AQ3: KRITERIA NILAI | BH3: SEKOLAH PEMBANDING
C4: 9 | D4: 8 | E4: 7 | F4: 6 | G4: 5 | H4: 4 | I4: 3 | J4: 2 | K4: 1 | L4: 2 | M4: 3 | N4: 4 | O4: 5 | P4: 6 | Q4: 7 | R4: 8 | S4: 9 | W4: 9 | X4: 8 | Y4: 7 | Z4: 6 | AA4: 5 | AB4: 4 | AC4: 3 | AD4: 2 | AE4: 1 | AF4: 2 | AG4: 3 | AH4: 4 | AI4: 5 | AJ4: 6 | AK4: 7 | AL4: 8 | AM4: 9 | AQ4: 9 | AR4: 8 | AS4: 7 | AT4: 6 | AU4: 5 | AV4: 4 | AW4: 3 | AX4: 2 | AY4: 1 | AZ4: 2 | BA4: 3 | BB4: 4 | BC4: 5 | BD4: 6 | BE4: 7 | BF4: 8 | BG4: 9
B5: SDN-2 ANJIR KALAMPAN | C5: 9 | D5: 8 | E5: 7 | F5: 6 | G5: 5 | H5: 4 | I5: 3 | J5: 2 | K5: 1 | L5: 2 | M5: 3 | N5: 4 | O5: 5 | P5: 6 | Q5: 7 | R5: 8 | S5: 9 | T5: SDN-3 ANJIR KALAMPAN | V5: SDN-2 ANJIR KALAMPAN | W5: 9 | X5: 8 | Y5: 7 | Z5: 6 | AA5: 5 | AB5: 4 | AC5: 3 | AD5: 2 | AE5: 1 | AF5: 2 | AG5: 3 | AH5: 4 | AI5: 5 | AJ5: 6 | AK5: 7 | AL5: 8 | AM5: 9 | AN5: SDN-3 ANJIR KALAMPAN | AP5: SDN-2 ANJIR KALAMPAN | AQ5: 9 | AR5: 8 | AS5: 7 | AT5: 6 | AU5: 5 | AV5: 4 | AW5: 3 | AX5: 2 | AY5: 1 | AZ5: 2 | BA5: 3 | BB5: 4 | BC5: 5 | BD5: 6 | BE5: 7 | BF5: 8 | BG5: 9 | BH5: SDN-3 ANJIR KALAMPAN | BJ5: PANDUAN PENGISIAN | BN5: CONDONG KE A | BV5: NETRAL | BW5: CONDONG KE B
B6: SDN-2 ANJIR KALAMPAN | C6: 9 | D6: 8 | E6: 7 | F6: 6 | G6: 5 | H6: 4 | I6: 3 | J6: 2 | K6: 1 | L6: 2 | M6: 3 | N6: 4 | O6: 5 | P6: 6 | Q6: 7 | R6: 8 | S6: 9 | T6: SDN-1 SAKA MANGKAHAI | V6: SDN-2 ANJIR KALAMPAN | W6: 9 | X6: 8 | Y6: 7 | Z6: 6 | AA6: 5 | AB6: 4 | AC6: 3 | AD6: 2 | AE6: 1 | AF6: 2 | AG6: 3 | AH6: 4 | AI6: 5 | AJ6: 6 | AK6: 7 | AL6: 8 | AM6: 9 | AN6: SDN-1 SAKA MANGKAHAI | AP6: SDN-2 ANJIR KALAMPAN | AQ6: 9 | AR6: 8 | AS6: 7 | AT6: 6 | AU6: 5 | AV6: 4 | AW6: 3 | AX6: 2 | AY6: 1 | AZ6: 2 | BA6: 3 | BB6: 4 | BC6: 5 | BD6: 6 | BE6: 7 | BF6: 8 | BG6: 9 | BH6: SDN-1 SAKA MANGKAHAI | BJ6: TINGKAT KEPENTINGAN | BK6: DEFINISI | BM6: PILIHAN A | BN6: 9 | BO6: 8 | BP6: 7 | BQ6: 6 | BR6: 5 | BS6: 4 | BT6: 3 | BU6: 2 | BV6: 1 | BW6: 2 | BX6: 3 | BY6: 4 | BZ6: 5 | CA6: 6 | CB6: 7 | CC6: 8 | CD6: 9 | CE6: PILIHAN B
B7: SDN-2 ANJIR KALAMPAN | C7: 9 | D7: 8 | E7: 7 | F7: 6 | G7: 5 | H7: 4 | I7: 3 | J7: 2 | K7: 1 | L7: 2 | M7: 3 | N7: 4 | O7: 5 | P7: 6 | Q7: 7 | R7: 8 | S7: 9 | T7: SDN-2 SAKA MANGKAHAI | V7: SDN-2 ANJIR KALAMPAN | W7: 9 | X7: 8 | Y7: 7 | Z7: 6 | AA7: 5 | AB7: 4 | AC7: 3 | AD7: 2 | AE7: 1 | AF7: 2 | AG7: 3 | AH7: 4 | AI7: 5 | AJ7: 6 | AK7: 7 | AL7: 8 | AM7: 9 | AN7: SDN-2 SAKA MANGKAHAI | AP7: SDN-2 ANJIR KALAMPAN | AQ7: 9 | AR7: 8 | AS7: 7 | AT7: 6 | AU7: 5 | AV7: 4 | AW7: 3 | AX7: 2 | AY7: 1 | AZ7: 2 | BA7: 3 | BB7: 4 | BC7: 5 | BD7: 6 | BE7: 7 | BF7: 8 | BG7: 9 | BH7: SDN-2 SAKA MANGKAHAI | BJ7: 1 | BK7: KEDUA ELEMEN SAMA PENTING
B8: SDN-2 ANJIR KALAMPAN | C8: 9 | D8: 8 | E8: 7 | F8: 6 | G8: 5 | H8: 4 | I8: 3 | J8: 2 | K8: 1 | L8: 2 | M8: 3 | N8: 4 | O8: 5 | P8: 6 | Q8: 7 | R8: 8 | S8: 9 | T8: SDN-2 MANDOMAI | V8: SDN-2 ANJIR KALAMPAN | W8: 9 | X8: 8 | Y8: 7 | Z8: 6 | AA8: 5 | AB8: 4 | AC8: 3 | AD8: 2 | AE8: 1 | AF8: 2 | AG8: 3 | AH8: 4 | AI8: 5 | AJ8: 6 | AK8: 7 | AL8: 8 | AM8: 9 | AN8: SDN-2 MANDOMAI | AP8: SDN-2 ANJIR KALAMPAN | AQ8: 9 | AR8: 8 | AS8: 7 | AT8: 6 | AU8: 5 | AV8: 4 | AW8: 3 | AX8: 2 | AY8: 1 | AZ8: 2 | BA8: 3 | BB8: 4 | BC8: 5 | BD8: 6 | BE8: 7 | BF8: 8 | BG8: 9 | BH8: SDN-2 MANDOMAI | BJ8: 3 | BK8: ELEMEN YANG SATU SEDIKIT LEBIH PENTING DARI YANG LAIN
B9: SDN-2 ANJIR KALAMPAN | C9: 9 | D9: 8 | E9: 7 | F9: 6 | G9: 5 | H9: 4 | I9: 3 | J9: 2 | K9: 1 | L9: 2 | M9: 3 | N9: 4 | O9: 5 | P9: 6 | Q9: 7 | R9: 8 | S9: 9 | T9: SDN-3 MANDOMAI | V9: SDN-2 ANJIR KALAMPAN | W9: 9 | X9: 8 | Y9: 7 | Z9: 6 | AA9: 5 | AB9: 4 | AC9: 3 | AD9: 2 | AE9: 1 | AF9: 2 | AG9: 3 | AH9: 4 | AI9: 5 | AJ9: 6 | AK9: 7 | AL9: 8 | AM9: 9 | AN9: SDN-3 MANDOMAI | AP9: SDN-2 ANJIR KALAMPAN | AQ9: 9 | AR9: 8 | AS9: 7 | AT9: 6 | AU9: 5 | AV9: 4 | AW9: 3 | AX9: 2 | AY9: 1 | AZ9: 2 | BA9: 3 | BB9: 4 | BC9: 5 | BD9: 6 | BE9: 7 | BF9: 8 | BG9: 9 | BH9: SDN-3 MANDOMAI | BJ9: 5 | BK9: ELEMEN YANG SATU LEBIH PENTING DARI YANG LAIN
B10: SDN-2 ANJIR KALAMPAN | C10: 9 | D10: 8 | E10: 7 | F10: 6 | G10: 5 | H10: 4 | I10: 3 | J10: 2 | K10: 1 | L10: 2 | M10: 3 | N10: 4 | O10: 5 | P10: 6 | Q10: 7 | R10: 8 | S10: 9 | T10: SDN-4 MANDOMAI | V10: SDN-2 ANJIR KALAMPAN | W10: 9 | X10: 8 | Y10: 7 | Z10: 6 | AA10: 5 | AB10: 4 | AC10: 3 | AD10: 2 | AE10: 1 | AF10: 2 | AG10: 3 | AH10: 4 | AI10: 5 | AJ10: 6 | AK10: 7 | AL10: 8 | AM10: 9 | AN10: SDN-4 MANDOMAI | AP10: SDN-2 ANJIR KALAMPAN | AQ10: 9 | AR10: 8 | AS10: 7 | AT10: 6 | AU10: 5 | AV10: 4 | AW10: 3 | AX10: 2 | AY10: 1 | AZ10: 2 | BA10: 3 | BB10: 4 | BC10: 5 | BD10: 6 | BE10: 7 | BF10: 8 | BG10: 9 | BH10: SDN-4 MANDOMAI | BJ10: 7 | BK10: ELEMEN YANG SATU SANGAT PENTING DARI YANG LAIN
B11: SDN-2 ANJIR KALAMPAN | C11: 9 | D11: 8 | E11: 7 | F11: 6 | G11: 5 | H11: 4 | I11: 3 | J11: 2 | K11: 1 | L11: 2 | M11: 3 | N11: 4 | O11: 5 | P11: 6 | Q11: 7 | R11: 8 | S11: 9 | T11: SDN-1 PANTAI | V11: SDN-2 ANJIR KALAMPAN | W11: 9 | X11: 8 | Y11: 7 | Z11: 6 | AA11: 5 | AB11: 4 | AC11: 3 | AD11: 2 | AE11: 1 | AF11: 2 | AG11: 3 | AH11: 4 | AI11: 5 | AJ11: 6 | AK11: 7 | AL11: 8 | AM11: 9 | AN11: SDN-1 PANTAI | AP11: SDN-2 ANJIR KALAMPAN | AQ11: 9 | AR11: 8 | AS11: 7 | AT11: 6 | AU11: 5 | AV11: 4 | AW11: 3 | AX11: 2 | AY11: 1 | AZ11: 2 | BA11: 3 | BB11: 4 | BC11: 5 | BD11: 6 | BE11: 7 | BF11: 8 | BG11: 9 | BH11: SDN-1 PANTAI | BJ11: 9 | BK11: ELEMEN YANG SATU MUTLAK LEBIH PENTING DARI YANG LAIN
B12: SDN-2 ANJIR KALAMPAN | C12: 9 | D12: 8 | E12: 7 | F12: 6 | G12: 5 | H12: 4 | I12: 3 | J12: 2 | K12: 1 | L12: 2 | M12: 3 | N12: 4 | O12: 5 | P12: 6 | Q12: 7 | R12: 8 | S12: 9 | T12: SDN-2 PANTAI | V12: SDN-2 ANJIR KALAMPAN | W12: 9 | X12: 8 | Y12: 7 | Z12: 6 | AA12: 5 | AB12: 4 | AC12: 3 | AD12: 2 | AE12: 1 | AF12: 2 | AG12: 3 | AH12: 4 | AI12: 5 | AJ12: 6 | AK12: 7 | AL12: 8 | AM12: 9 | AN12: SDN-2 PANTAI | AP12: SDN-2 ANJIR KALAMPAN | AQ12: 9 | AR12: 8 | AS12: 7 | AT12: 6 | AU12: 5 | AV12: 4 | AW12: 3 | AX12: 2 | AY12: 1 | AZ12: 2 | BA12: 3 | BB12: 4 | BC12: 5 | BD12: 6 | BE12: 7 | BF12: 8 | BG12: 9 | BH12: SDN-2 PANTAI | BJ12: 2,4,6,8 | BK12: NILAI KOMPROMI (NILAI TENGAH ANTARA DUA PERBANDINGAN)
B13: SDN-2 ANJIR KALAMPAN | C13: 9 | D13: 8 | E13: 7 | F13: 6 | G13: 5 | H13: 4 | I13: 3 | J13: 2 | K13: 1 | L13: 2 | M13: 3 | N13: 4 | O13: 5 | P13: 6 | Q13: 7 | R13: 8 | S13: 9 | T13: SDN-1 BASUTA RAYA | V13: SDN-2 ANJIR KALAMPAN | W13: 9 | X13: 8 | Y13: 7 | Z13: 6 | AA13: 5 | AB13: 4 | AC13: 3 | AD13: 2 | AE13: 1 | AF13: 2 | AG13: 3 | AH13: 4 | AI13: 5 | AJ13: 6 | AK13: 7 | AL13: 8 | AM13: 9 | AN13: SDN-1 BASUTA RAYA | AP13: SDN-2 ANJIR KALAMPAN | AQ13: 9 | AR13: 8 | AS13: 7 | AT13: 6 | AU13: 5 | AV13: 4 | AW13: 3 | AX13: 2 | AY13: 1 | AZ13: 2 | BA13: 3 | BB13: 4 | BC13: 5 | BD13: 6 | BE13: 7 | BF13: 8 | BG13: 9 | BH13: SDN-1 BASUTA RAYA
B14: SDN-2 ANJIR KALAMPAN | C14: 9 | D14: 8 | E14: 7 | F14: 6 | G14: 5 | H14: 4 | I14: 3 | J14: 2 | K14: 1 | L14: 2 | M14: 3 | N14: 4 | O14: 5 | P14: 6 | Q14: 7 | R14: 8 | S14: 9 | T14: SDN-1 SEI PITUNG | V14: SDN-2 ANJIR KALAMPAN | W14: 9 | X14: 8 | Y14: 7 | Z14: 6 | AA14: 5 | AB14: 4 | AC14: 3 | AD14: 2 | AE14: 1 | AF14: 2 | AG14: 3 | AH14: 4 | AI14: 5 | AJ14: 6 | AK14: 7 | AL14: 8 | AM14: 9 | AN14: SDN-1 SEI PITUNG | AP14: SDN-2 ANJIR KALAMPAN | AQ14: 9 | AR14: 8 | AS14: 7 | AT14: 6 | AU14: 5 | AV14: 4 | AW14: 3 | AX14: 2 | AY14: 1 | AZ14: 2 | BA14: 3 | BB14: 4 | BC14: 5 | BD14: 6 | BE14: 7 | BF14: 8 | BG14: 9 | BH14: SDN-1 SEI PITUNG
B15: SDN-2 ANJIR KALAMPAN | C15: 9 | D15: 8 | E15: 7 | F15: 6 | G15: 5 | H15: 4 | I15: 3 | J15: 2 | K15: 1 | L15: 2 | M15: 3 | N15: 4 | O15: 5 | P15: 6 | Q15: 7 | R15: 8 | S15: 9 | T15: SDN-1 PENDA KATAPI | V15: SDN-2 ANJIR KALAMPAN | W15: 9 | X15: 8 | Y15: 7 | Z15: 6 | AA15: 5 | AB15: 4 | AC15: 3 | AD15: 2 | AE15: 1 | AF15: 2 | AG15: 3 | AH15: 4 | AI15: 5 | AJ15: 6 | AK15: 7 | AL15: 8 | AM15: 9 | AN15: SDN-1 PENDA KATAPI | AP15: SDN-2 ANJIR KALAMPAN | AQ15: 9 | AR15: 8 | AS15: 7 | AT15: 6 | AU15: 5 | AV15: 4 | AW15: 3 | AX15: 2 | AY15: 1 | AZ15: 2 | BA15: 3 | BB15: 4 | BC15: 5 | BD15: 6 | BE15: 7 | BF15: 8 | BG15: 9 | BH15: SDN-1 PENDA KATAPI
B16: SDN-2 ANJIR KALAMPAN | C16: 9 | D16: 8 | E16: 7 | F16: 6 | G16: 5 | H16: 4 | I16: 3 | J16: 2 | K16: 1 | L16: 2 | M16: 3 | N16: 4 | O16: 5 | P16: 6 | Q16: 7 | R16: 8 | S16: 9 | T16: SDN-1 SEI KAYU | V16: SDN-2 ANJIR KALAMPAN | W16: 9 | X16: 8 | Y16: 7 | Z16: 6 | AA16: 5 | AB16: 4 | AC16: 3 | AD16: 2 | AE16: 1 | AF16: 2 | AG16: 3 | AH16: 4 | AI16: 5 | AJ16: 6 | AK16: 7 | AL16: 8 | AM16: 9 | AN16: SDN-1 SEI KAYU | AP16: SDN-2 ANJIR KALAMPAN | AQ16: 9 | AR16: 8 | AS16: 7 | AT16: 6 | AU16: 5 | AV16: 4 | AW16: 3 | AX16: 2 | AY16: 1 | AZ16: 2 | BA16: 3 | BB16: 4 | BC16: 5 | BD16: 6 | BE16: 7 | BF16: 8 | BG16: 9 | BH16: SDN-1 SEI KAYU
B17: SDN-2 ANJIR KALAMPAN | C17: 9 | D17: 8 | E17: 7 | F17: 6 | G17: 5 | H17: 4 | I17: 3 | J17: 2 | K17: 1 | L17: 2 | M17: 3 | N17: 4 | O17: 5 | P17: 6 | Q17: 7 | R17: 8 | S17: 9 | T17: SDN-2 SEI KAYU | V17: SDN-2 ANJIR KALAMPAN | W17: 9 | X17: 8 | Y17: 7 | Z17: 6 | AA17: 5 | AB17: 4 | AC17: 3 | AD17: 2 | AE17: 1 | AF17: 2 | AG17: 3 | AH17: 4 | AI17: 5 | AJ17: 6 | AK17: 7 | AL17: 8 | AM17: 9 | AN17: SDN-2 SEI KAYU | AP17: SDN-2 ANJIR KALAMPAN | AQ17: 9 | AR17: 8 | AS17: 7 | AT17: 6 | AU17: 5 | AV17: 4 | AW17: 3 | AX17: 2 | AY17: 1 | AZ17: 2 | BA17: 3 | BB17: 4 | BC17: 5 | BD17: 6 | BE17: 7 | BF17: 8 | BG17: 9 | BH17: SDN-2 SEI KAYU
B18: SDN-2 ANJIR KALAMPAN | C18: 9 | D18: 8 | E18: 7 | F18: 6 | G18: 5 | H18: 4 | I18: 3 | J18: 2 | K18: 1 | L18: 2 | M18: 3 | N18: 4 | O18: 5 | P18: 6 | Q18: 7 | R18: 8 | S18: 9 | T18: SDN-1 SEI DUSUN | V18: SDN-2 ANJIR KALAMPAN | W18: 9 | X18: 8 | Y18: 7 | Z18: 6 | AA18: 5 | AB18: 4 | AC18: 3 | AD18: 2 | AE18: 1 | AF18: 2 | AG18: 3 | AH18: 4 | AI18: 5 | AJ18: 6 | AK18: 7 | AL18: 8 | AM18: 9 | AN18: SDN-1 SEI DUSUN | AP18: SDN-2 ANJIR KALAMPAN | AQ18: 9 | AR18: 8 | AS18: 7 | AT18: 6 | AU18: 5 | AV18: 4 | AW18: 3 | AX18: 2 | AY18: 1 | AZ18: 2 | BA18: 3 | BB18: 4 | BC18: 5 | BD18: 6 | BE18: 7 | BF18: 8 | BG18: 9 | BH18: SDN-1 SEI DUSUN
B19: SDN-3 ANJIR KALAMPAN | C19: 9 | D19: 8 | E19: 7 | F19: 6 | G19: 5 | H19: 4 | I19: 3 | J19: 2 | K19: 1 | L19: 2 | M19: 3 | N19: 4 | O19: 5 | P19: 6 | Q19: 7 | R19: 8 | S19: 9 | T19: SDN-1 SAKA MANGKAHAI | V19: SDN-3 ANJIR KALAMPAN | W19: 9 | X19: 8 | Y19: 7 | Z19: 6 | AA19: 5 | AB19: 4 | AC19: 3 | AD19: 2 | AE19: 1 | AF19: 2 | AG19: 3 | AH19: 4 | AI19: 5 | AJ19: 6 | AK19: 7 | AL19: 8 | AM19: 9 | AN19: SDN-1 SAKA MANGKAHAI | AP19: SDN-3 ANJIR KALAMPAN | AQ19: 9 | AR19: 8 | AS19: 7 | AT19: 6 | AU19: 5 | AV19: 4 | AW19: 3 | AX19: 2 | AY19: 1 | AZ19: 2 | BA19: 3 | BB19: 4 | BC19: 5 | BD19: 6 | BE19: 7 | BF19: 8 | BG19: 9 | BH19: SDN-1 SAKA MANGKAHAI
B20: SDN-3 ANJIR KALAMPAN | C20: 9 | D20: 8 | E20: 7 | F20: 6 | G20: 5 | H20: 4 | I20: 3 | J20: 2 | K20: 1 | L20: 2 | M20: 3 | N20: 4 | O20: 5 | P20: 6 | Q20: 7 | R20: 8 | S20: 9 | T20: SDN-2 SAKA MANGKAHAI | V20: SDN-3 ANJIR KALAMPAN | W20: 9 | X20: 8 | Y20: 7 | Z20: 6 | AA20: 5 | AB20: 4 | AC20: 3 | AD20: 2 | AE20: 1 | AF20: 2 | AG20: 3 | AH20: 4 | AI20: 5 | AJ20: 6 | AK20: 7 | AL20: 8 | AM20: 9 | AN20: SDN-2 SAKA MANGKAHAI | AP20: SDN-3 ANJIR KALAMPAN | AQ20: 9 | AR20: 8 | AS20: 7 | AT20: 6 | AU20: 5 | AV20: 4 | AW20: 3 | AX20: 2 | AY20: 1 | AZ20: 2 | BA20: 3 | BB20: 4 | BC20: 5 | BD20: 6 | BE20: 7 | BF20: 8 | BG20: 9 | BH20: SDN-2 SAKA MANGKAHAI
B21: SDN-3 ANJIR KALAMPAN | C21: 9 | D21: 8 | E21: 7 | F21: 6 | G21: 5 | H21: 4 | I21: 3 | J21: 2 | K21: 1 | L21: 2 | M21: 3 | N21: 4 | O21: 5 | P21: 6 | Q21: 7 | R21: 8 | S21: 9 | T21: SDN-2 MANDOMAI | V21: SDN-3 ANJIR KALAMPAN | W21: 9 | X21: 8 | Y21: 7 | Z21: 6 | AA21: 5 | AB21: 4 | AC21: 3 | AD21: 2 | AE21: 1 | AF21: 2 | AG21: 3 | AH21: 4 | AI21: 5 | AJ21: 6 | AK21: 7 | AL21: 8 | AM21: 9 | AN21: SDN-2 MANDOMAI | AP21: SDN-3 ANJIR KALAMPAN | AQ21: 9 | AR21: 8 | AS21: 7 | AT21: 6 | AU21: 5 | AV21: 4 | AW21: 3 | AX21: 2 | AY21: 1 | AZ21: 2 | BA21: 3 | BB21: 4 | BC21: 5 | BD21: 6 | BE21: 7 | BF21: 8 | BG21: 9 | BH21: SDN-2 MANDOMAI
B22: SDN-3 ANJIR KALAMPAN | C22: 9 | D22: 8 | E22: 7 | F22: 6 | G22: 5 | H22: 4 | I22: 3 | J22: 2 | K22: 1 | L22: 2 | M22: 3 | N22: 4 | O22: 5 | P22: 6 | Q22: 7 | R22: 8 | S22: 9 | T22: SDN-3 MANDOMAI | V22: SDN-3 ANJIR KALAMPAN | W22: 9 | X22: 8 | Y22: 7 | Z22: 6 | AA22: 5 | AB22: 4 | AC22: 3 | AD22: 2 | AE22: 1 | AF22: 2 | AG22: 3 | AH22: 4 | AI22: 5 | AJ22: 6 | AK22: 7 | AL22: 8 | AM22: 9 | AN22: SDN-3 MANDOMAI | AP22: SDN-3 ANJIR KALAMPAN | AQ22: 9 | AR22: 8 | AS22: 7 | AT22: 6 | AU22: 5 | AV22: 4 | AW22: 3 | AX22: 2 | AY22: 1 | AZ22: 2 | BA22: 3 | BB22: 4 | BC22: 5 | BD22: 6 | BE22: 7 | BF22: 8 | BG22: 9 | BH22: SDN-3 MANDOMAI
B23: SDN-3 ANJIR KALAMPAN | C23: 9 | D23: 8 | E23: 7 | F23: 6 | G23: 5 | H23: 4 | I23: 3 | J23: 2 | K23: 1 | L23: 2 | M23: 3 | N23: 4 | O23: 5 | P23: 6 | Q23: 7 | R23: 8 | S23: 9 | T23: SDN-4 MANDOMAI | V23: SDN-3 ANJIR KALAMPAN | W23: 9 | X23: 8 | Y23: 7 | Z23: 6 | AA23: 5 | AB23: 4 | AC23: 3 | AD23: 2 | AE23: 1 | AF23: 2 | AG23: 3 | AH23: 4 | AI23: 5 | AJ23: 6 | AK23: 7 | AL23: 8 | AM23: 9 | AN23: SDN-4 MANDOMAI | AP23: SDN-3 ANJIR KALAMPAN | AQ23: 9 | AR23: 8 | AS23: 7 | AT23: 6 | AU23: 5 | AV23: 4 | AW23: 3 | AX23: 2 | AY23: 1 | AZ23: 2 | BA23: 3 | BB23: 4 | BC23: 5 | BD23: 6 | BE23: 7 | BF23: 8 | BG23: 9 | BH23: SDN-4 MANDOMAI
B24: SDN-3 ANJIR KALAMPAN | C24: 9 | D24: 8 | E24: 7 | F24: 6 | G24: 5 | H24: 4 | I24: 3 | J24: 2 | K24: 1 | L24: 2 | M24: 3 | N24: 4 | O24: 5 | P24: 6 | Q24: 7 | R24: 8 | S24: 9 | T24: SDN-1 PANTAI | V24: SDN-3 ANJIR KALAMPAN | W24: 9 | X24: 8 | Y24: 7 | Z24: 6 | AA24: 5 | AB24: 4 | AC24: 3 | AD24: 2 | AE24: 1 | AF24: 2 | AG24: 3 | AH24: 4 | AI24: 5 | AJ24: 6 | AK24: 7 | AL24: 8 | AM24: 9 | AN24: SDN-1 PANTAI | AP24: SDN-3 ANJIR KALAMPAN | AQ24: 9 | AR24: 8 | AS24: 7 | AT24: 6 | AU24: 5 | AV24: 4 | AW24: 3 | AX24: 2 | AY24: 1 | AZ24: 2 | BA24: 3 | BB24: 4 | BC24: 5 | BD24: 6 | BE24: 7 | BF24: 8 | BG24: 9 | BH24: SDN-1 PANTAI
... B109: SDN-2 SEI KAYU | C109: 9 | D109: 8 | E109: 7 | F109: 6 | G109: 5 | H109: 4 | I109: 3 | J109: 2 | K109: 1 | L109: 2 | M109: 3 | N109: 4 | O109: 5 | P109: 6 | Q109: 7 | R109: 8 | S109: 9 | T109: SDN-1 SEI DUSUN | V109: SDN-2 SEI KAYU | W109: 9 | X109: 8 | Y109: 7 | Z109: 6 | AA109: 5 | AB109: 4 | AC109: 3 | AD109: 2 | AE109: 1 | AF109: 2 | AG109: 3 | AH109: 4 | AI109: 5 | AJ109: 6 | AK109: 7 | AL109: 8 | AM109: 9 | AN109: SDN-1 SEI DUSUN | AP109: SDN-2 SEI KAYU | AQ109: 9 | AR109: 8 | AS109: 7 | AT109: 6 | AU109: 5 | AV109: 4 | AW109: 3 | AX109: 2 | AY109: 1 | AZ109: 2 | BA109: 3 | BB109: 4 | BC109: 5 | BD109: 6 | BE109: 7 | BF109: 8 | BG109: 9 | BH109: SDN-1 SEI DUSUN

Sheet JUMLAH SISWA
B1: JUMLAH SISWA | V1: JUMLAH SISWA | AP1: JUMLAH SISWA
B2: PENGAWAS SEKOLAH DASAR KAPUAS BARAT (JHON) | V2: KEPALA BIDANG PENGAWASAN SEKOLAH DASAR DISDIK KAPUAS (JEFRI) | AP2: KOMISI IV DPRD KAB. KAPUAS
B3: SEKOLAH UTAMA | C3: KRITERIA NILAI | T3: SEKOLAH PEMBANDING | V3: SEKOLAH UTAMA | W3: KRITERIA NILAI | AN3: SEKOLAH PEMBANDING | AP3: SEKOLAH UTAMA | AQ3: KRITERIA NILAI | BH3: SEKOLAH PEMBANDING
C4: 9 | D4: 8 | E4: 7 | F4: 6 | G4: 5 | H4: 4 | I4: 3 | J4: 2 | K4: 1 | L4: 2 | M4: 3 | N4: 4 | O4: 5 | P4: 6 | Q4: 7 | R4: 8 | S4: 9 | W4: 9 | X4: 8 | Y4: 7 | Z4: 6 | AA4: 5 | AB4: 4 | AC4: 3 | AD4: 2 | AE4: 1 | AF4: 2 | AG4: 3 | AH4: 4 | AI4: 5 | AJ4: 6 | AK4: 7 | AL4: 8 | AM4: 9 | AQ4: 9 | AR4: 8 | AS4: 7 | AT4: 6 | AU4: 5 | AV4: 4 | AW4: 3 | AX4: 2 | AY4: 1 | AZ4: 2 | BA4: 3 | BB4: 4 | BC4: 5 | BD4: 6 | BE4: 7 | BF4: 8 | BG4: 9
B5: SDN-2 ANJIR KALAMPAN | C5: 9 | D5: 8 | E5: 7 | F5: 6 | G5: 5 | H5: 4 | I5: 3 | J5: 2 | K5: 1 | L5: 2 | M5: 3 | N5: 4 | O5: 5 | P5: 6 | Q5: 7 | R5: 8 | S5: 9 | T5: SDN-3 ANJIR KALAMPAN | V5: SDN-2 ANJIR KALAMPAN | W5: 9 | X5: 8 | Y5: 7 | Z5: 6 | AA5: 5 | AB5: 4 | AC5: 3 | AD5: 2 | AE5: 1 | AF5: 2 | AG5: 3 | AH5: 4 | AI5: 5 | AJ5: 6 | AK5: 7 | AL5: 8 | AM5: 9 | AN5: SDN-3 ANJIR KALAMPAN | AP5: SDN-2 ANJIR KALAMPAN | AQ5: 9 | AR5: 8 | AS5: 7 | AT5: 6 | AU5: 5 | AV5: 4 | AW5: 3 | AX5: 2 | AY5: 1 | AZ5: 2 | BA5: 3 | BB5: 4 | BC5: 5 | BD5: 6 | BE5: 7 | BF5: 8 | BG5: 9 | BH5: SDN-3 ANJIR KALAMPAN | BJ5: PANDUAN PENGISIAN | BN5: CONDONG KE A | BV5: NETRAL | BW5: CONDONG KE B
B6: SDN-2 ANJIR KALAMPAN | C6: 9 | D6: 8 | E6: 7 | F6: 6 | G6: 5 | H6: 4 | I6: 3 | J6: 2 | K6: 1 | L6: 2 | M6: 3 | N6: 4 | O6: 5 | P6: 6 | Q6: 7 | R6: 8 | S6: 9 | T6: SDN-1 SAKA MANGKAHAI | V6: SDN-2 ANJIR KALAMPAN | W6: 9 | X6: 8 | Y6: 7 | Z6: 6 | AA6: 5 | AB6: 4 | AC6: 3 | AD6: 2 | AE6: 1 | AF6: 2 | AG6: 3 | AH6: 4 | AI6: 5 | AJ6: 6 | AK6: 7 | AL6: 8 | AM6: 9 | AN6: SDN-1 SAKA MANGKAHAI | AP6: SDN-2 ANJIR KALAMPAN | AQ6: 9 | AR6: 8 | AS6: 7 | AT6: 6 | AU6: 5 | AV6: 4 | AW6: 3 | AX6: 2 | AY6: 1 | AZ6: 2 | BA6: 3 | BB6: 4 | BC6: 5 | BD6: 6 | BE6: 7 | BF6: 8 | BG6: 9 | BH6: SDN-1 SAKA MANGKAHAI | BJ6: TINGKAT KEPENTINGAN | BK6: DEFINISI | BM6: PILIHAN A | BN6: 9 | BO6: 8 | BP6: 7 | BQ6: 6 | BR6: 5 | BS6: 4 | BT6: 3 | BU6: 2 | BV6: 1 | BW6: 2 | BX6: 3 | BY6: 4 | BZ6: 5 | CA6: 6 | CB6: 7 | CC6: 8 | CD6: 9 | CE6: PILIHAN B
